Workbook

Sheet 总表
L8: 备注
L9: 1.桑多涅为风起套，30词。24双爆＋4攻＋2精
F10: v5木偶星扩散 | L10: 2.奥黛塔为炉火，30词。24双爆＋4攻＋2精，携带主角专武
F11: 偶/奥 | G11: 0+0 | H11: 1+0 | I11: 2+0 | L11: 3.布伦尼讨龙，风套
F12: 0+1 | G12: ='0＋1桑0奥'!C3 -> 164772.39 | H12: ='0＋1桑0奥'!C77 -> 183179.66 | I12: ='0＋1桑0奥'!C152 -> 225566.29 | L12: 4.此计算为第二轮开始循环计算，热启动
F13: 1+1 | G13: ='1+1桑0奥'!C3 -> 174600.17 | H13: ='1+1桑0奥'!C72 -> 192364.52 | I13: ='1+1桑0奥'!C142 -> 238227.21
F14: 2+1 | G14: ='2+1桑0奥 '!C3 -> 191528.49 | H14: ='2+1桑0奥 '!C72 -> 215344.68 | I14: ='2+1桑0奥 '!C142 -> 267728.58
F15: 6+1 | G15: ='6+1桑0奥 '!C3 -> 315399.34 | H15: ='6+1桑0奥 '!C92 -> 348150.2 | I15: ='6+1桑0奥 '!C176 -> 432187.49

Sheet 0＋1桑0奥
A1: 0＋1桑多涅0＋星峰剑奥c6布0七 | F1: mc | G1: 攻击力 | H1: 倍率 | I1: 基础系数 | J1: 独立 | K1: 基础乘区 | L1: 精通 | M1: 星扩增 | N1: 精通乘区 | O1: 羽毛 | P1: 暴击率 | Q1: 爆伤 | R1: 暴击乘区 | S1: 抗性系数 | T1: 擢升 | U1: 单次伤害 | V1: 总伤
A2: 统计 | B2: DMG | C2: DPS | D2: 轴长 | F2: z | G2: =3199+488+203 -> 3890 | H2: 2.4225 | I2: 1.28 | J2: 1 | K2: =G2*H2*I2*J2 -> 12062.112 | L2: 200 | M2: 1.93 | N2: =1+6*L2/(L2+2000)+M2 -> 3.4754545 | O2: 0 | P2: 0.85 | Q2: 2.22 | R2: =1+P2*Q2 -> 2.887 | S2: 1.15 | T2: 1 | U2: =(K2*N2+O2)*R2*S2*T2 -> 139180.89 | V2: =SUM(U2:U14) -> 2215344
B3: =B5+B7+B9 -> 3295447.7 | C3: =B3/D3 -> 164772.39 | D3: 20 | F3: z | G3: =3199+488+203 -> 3890 | H3: 2.4225 | I3: 1.28 | J3: 1 | K3: =G3*H3*I3*J3 -> 12062.112 | L3: 200 | M3: 2.08 | N3: =1+6*L3/(L3+2000)+M3 -> 3.6254545 | O3: 0 | P3: 0.85 | Q3: 2.22 | R3: =1+P3*Q3 -> 2.887 | S3: 1.15 | T3: 1 | U3: =(K3*N3+O3)*R3*S3*T3 -> 145187.91
B4: 桑多涅总伤 | C4: 占比 | F4: z | G4: =3199+488+203 -> 3890 | H4: 2.4225 | I4: 1.28 | J4: 1 | K4: =G4*H4*I4*J4 -> 12062.112 | L4: 200 | M4: 2.08 | N4: =1+6*L4/(L4+2000)+M4 -> 3.6254545 | O4: 0 | P4: 0.85 | Q4: 2.22 | R4: =1+P4*Q4 -> 2.887 | S4: 1.15 | T4: 1 | U4: =(K4*N4+O4)*R4*S4*T4 -> 145187.91
B5: =V2+T18 -> 2561999.7 | C5: =B5/B3 -> 0.77743599 | F5: e | G5: =3199+488+203 -> 3890 | H5: 0.5832 | I5: 1.28 | J5: 4 | K5: =G5*H5*I5*J5 -> 11615.478 | L5: 200 | M5: 2.08 | N5: =1+6*L5/(L5+2000)+M5 -> 3.6254545 | O5: 0 | P5: 0.85 | Q5: 2.22 | R5: =1+P5*Q5 -> 2.887 | S5: 1.15 | T5: 1 | U5: =(K5*N5+O5)*R5*S5*T5 -> 139811.91
B6: 奥黛塔总伤 | C6: 占比 | F6: q | G6: =3199+488+203 -> 3890 | H6: 5.9544 | I6: 1.28 | J6: 2 | K6: =G6*H6*I6*J6 -> 59296.297 | L6: 200 | M6: 2.08 | N6: =1+6*L6/(L6+2000)+M6 -> 3.6254545 | O6: 0 | P6: 0.85 | Q6: 2.22 | R6: =1+P6*Q6 -> 2.887 | S6: 1.15 | T6: 1 | U6: =(K6*N6+O6)*R6*S6*T6 -> 713731.17
B7: =V28+T40 -> 557847.12 | C7: =B7/B3 -> 0.1692781 | F7: z | G7: =3199+488+203 -> 3890 | H7: 2.4225 | I7: 1.28 | J7: 1 | K7: =G7*H7*I7*J7 -> 12062.112 | L7: 200 | M7: 2.08 | N7: =1+6*L7/(L7+2000)+M7 -> 3.6254545 | O7: 0 | P7: 0.85 | Q7: 2.22 | R7: =1+P7*Q7 -> 2.887 | S7: 1.15 | T7: 1 | U7: =(K7*N7+O7)*R7*S7*T7 -> 145187.91
B8: 反应伤害 | C8: 占比 | F8: z | G8: =3199+488+203 -> 3890 | H8: 2.4225 | I8: 1.28 | J8: 1 | K8: =G8*H8*I8*J8 -> 12062.112 | L8: 200 | M8: 2.08 | N8: =1+6*L8/(L8+2000)+M8 -> 3.6254545 | O8: 0 | P8: 0.85 | Q8: 2.22 | R8: =1+P8*Q8 -> 2.887 | S8: 1.15 | T8: 1 | U8: =(K8*N8+O8)*R8*S8*T8 -> 145187.91
B9: =U45+U51+U57+U63 -> 175600.94 | C9: =B9/B3 -> 0.053285913 | F9: z | G9: =3199+488+203 -> 3890 | H9: 2.4225 | I9: 1.28 | J9: 1 | K9: =G9*H9*I9*J9 -> 12062.112 | L9: 200 | M9: 2.08 | N9: =1+6*L9/(L9+2000)+M9 -> 3.6254545 | O9: 0 | P9: 0.85 | Q9: 2.22 | R9: =1+P9*Q9 -> 2.887 | S9: 1.15 | T9: 1 | U9: =(K9*N9+O9)*R9*S9*T9 -> 145187.91
F10: e | G10: =3199+488+203 -> 3890 | H10: 0.5832 | I10: 1.28 | J10: 4 | K10: =G10*H10*I10*J10 -> 11615.478 | L10: 200 | M10: 2.08 | N10: =1+6*L10/(L10+2000)+M10 -> 3.6254545 | O10: 0 | P10: 0.85 | Q10: 2.22 | R10: =1+P10*Q10 -> 2.887 | S10: 1.15 | T10: 1 | U10: =(K10*N10+O10)*R10*S10*T10 -> 139811.91
F11: z | G11: =3199+203 -> 3402 | H11: 2.4225 | I11: 1.28 | J11: 1 | K11: =G11*H11*I11*J11 -> 10548.922 | L11: 200 | M11: 2.08 | N11: =1+6*L11/(L11+2000)+M11 -> 3.6254545 | O11: 0 | P11: 0.85 | Q11: 2.22 | R11: =1+P11*Q11 -> 2.887 | S11: 0.9 | T11: 1 | U11: =(K11*N11+O11)*R11*S11*T11 -> 99371.037
F12: z | G12: =3199+203 -> 3402 | H12: 2.4225 | I12: 1.28 | J12: 1 | K12: =G12*H12*I12*J12 -> 10548.922 | L12: 200 | M12: 2.08 | N12: =1+6*L12/(L12+2000)+M12 -> 3.6254545 | O12: 0 | P12: 0.85 | Q12: 2.22 | R12: =1+P12*Q12 -> 2.887 | S12: 0.9 | T12: 1 | U12: =(K12*N12+O12)*R12*S12*T12 -> 99371.037
F13: z | G13: =3199 -> 3199 | H13: 2.4225 | I13: 1.28 | J13: 1 | K13: =G13*H13*I13*J13 -> 9919.4592 | L13: 200 | M13: 1.58 | N13: =1+6*L13/(L13+2000)+M13 -> 3.1254545 | O13: 0 | P13: 0.85 | Q13: 2.22 | R13: =1+P13*Q13 -> 2.887 | S13: 0.9 | T13: 1 | U13: =(K13*N13+O13)*R13*S13*T13 -> 80554.624
F14: e | G14: =3199 -> 3199 | H14: 0.5832 | I14: 1.28 | J14: 4 | K14: =G14*H14*I14*J14 -> 9552.1628 | L14: 200 | M14: 1.58 | N14: =1+6*L14/(L14+2000)+M14 -> 3.1254545 | O14: 0 | P14: 0.85 | Q14: 2.22 | R14: =1+P14*Q14 -> 2.887 | S14: 0.9 | T14: 1 | U14: =(K14*N14+O14)*R14*S14*T14 -> 77571.859
G17: 攻击力 | H17: 倍率 | I17: 独立 | J17: 独立 | K17: 基础乘区 | L17: 冰增伤 | M17: 暴击率 | N17: 爆伤 | O17: 暴击乘区 | P17: 抗性系数 | Q17: 单次伤害 | R17: 次数 | S17: 单总伤 | T17: 总伤
G18: =3199+488+203 -> 3890 | H18: 0.85 | I18: 1 | J18: 1 | K18: =G18*H18*I18*J18 -> 3306.5 | L18: 1 | M18: 0.85 | N18: 2.22 | O18: =1+M18*N18 -> 2.887 | P18: 1.15 | Q18: =K18*L18*O18*P18 -> 10977.745 | R18: 9 | S18: =Q18*R18 -> 98799.708 | T18: =SUM(S18:S24) -> 346655.7
G19: =3199+488+203 -> 3890 | H19: 0.5832 | I19: 1 | J19: 1 | K19: =G19*H19*I19*J19 -> 2268.648 | L19: 1 | M19: 0.85 | N19: 2.22 | O19: =1+M19*N19 -> 2.887 | P19: 1.15 | Q19: =K19*L19*O19*P19 -> 7532.0248 | R19: 1 | S19: =Q19*R19 -> 7532.0248
G20: =3199+488+203 -> 3890 | H20: 1.5879 | I20: 3 | J20: 1 | K20: =G20*H20*I20*J20 -> 18530.793 | L20: 1 | M20: 0.85 | N20: 2.22 | O20: =1+M20*N20 -> 2.887 | P20: 1.15 | Q20: =K20*L20*O20*P20 -> 61523.159 | R20: 1 | S20: =Q20*R20 -> 61523.159
G21: =3199+488+203 -> 3890 | H21: 0.85 | I21: 1 | J21: 1 | K21: =G21*H21*I21*J21 -> 3306.5 | L21: 1 | M21: 0.85 | N21: 2.22 | O21: =1+M21*N21 -> 2.887 | P21: 1.15 | Q21: =K21*L21*O21*P21 -> 10977.745 | R21: 9 | S21: =Q21*R21 -> 98799.708
G22: =3199+488+203 -> 3890 | H22: 0.5832 | I22: 1 | J22: 1 | K22: =G22*H22*I22*J22 -> 2268.648 | L22: 1 | M22: 0.85 | N22: 2.22 | O22: =1+M22*N22 -> 2.887 | P22: 1.15 | Q22: =K22*L22*O22*P22 -> 7532.0248 | R22: 1 | S22: =Q22*R22 -> 7532.0248
G23: =$G12 -> 3402 | H23: 0.85 | I23: 1 | J23: 1 | K23: =G23*H23*I23*J23 -> 2891.7 | L23: 1 | M23: 0.85 | N23: 2.22 | O23: =1+M23*N23 -> 2.887 | P23: 0.9 | Q23: =K23*L23*O23*P23 -> 7513.5041 | R23: 9 | S23: =Q23*R23 -> 67621.537
G24: =$G14 -> 3199 | H24: 0.5832 | I24: 1 | J24: 1 | K24: =G24*H24*I24*J24 -> 1865.6568 | L24: 1 | M24: 0.85 | N24: 2.22 | O24: =1+M24*N24 -> 2.887 | P24: 0.9 | Q24: =K24*L24*O24*P24 -> 4847.5361 | R24: 1 | S24: =Q24*R24 -> 4847.5361
F26: 奥黛塔
F27: mc | G27: 攻击力 | H27: 倍率 | I27: 基础系数 | J27: 独立 | K27: 基础乘区 | L27: 精通 | M27: 星扩增 | N27: 精通乘区 | O27: 羽毛 | P27: 暴击率 | Q27: 爆伤 | R27: 暴击乘区 | S27: 抗性系数 | T27: 擢升 | U27: 单次伤害 | V27: 总伤
F28: ee | G28: 2604 | H28: 8.2555 | I28: 1.28 | J28: =16*0.015+1 -> 1.24 | K28: =G28*H28*I28*J28 -> 34120.549 | L28: 20 | M28: 1.1 | N28: =1+6*L28/(L28+2000)+M28 -> 2.1594059 | O28: 0 | P28: 0.93 | Q28: 2.3 | R28: =1+P28*Q28 -> 3.139 | S28: 0.9 | T28: 1 | U28: =(K28*N28+O28)*R28*S28*T28 -> 208153.7 | V28: =SUM(U28:U37) -> 421028.49
F29: e1 | G29: =189+2604 -> 2793 | H29: 0.7295 | I29: 1.28 | J29: =17*0.015+1 -> 1.255 | K29: =G29*H29*I29*J29 -> 3273.0296 | L29: 20 | M29: 1.3 | N29: =1+6*L29/(L29+2000)+M29 -> 2.3594059 | O29: 0 | P29: 0.93 | Q29: 2.3 | R29: =1+P29*Q29 -> 3.139 | S29: 0.9 | T29: 1 | U29: =(K29*N29+O29)*R29*S29*T29 -> 21816.567
F30: e2 | G30: =189+2604 -> 2793 | H30: 0.8724 | I30: 1.28 | J30: =17*0.015+1 -> 1.255 | K30: =G30*H30*I30*J30 -> 3914.1754 | L30: 20 | M30: 1 | N30: =1+6*L30/(L30+2000)+M30 -> 2.0594059 | O30: 0 | P30: 0.93 | Q30: 2.3 | R30: =1+P30*Q30 -> 3.139 | S30: 1.15 | T30: 1 | U30: =(K30*N30+O30)*R30*S30*T30 -> 29098.554
F31: e3 | G31: =189+2604 -> 2793 | H31: 0.7295 | I31: 1.28 | J31: =17*0.015+1 -> 1.255 | K31: =G31*H31*I31*J31 -> 3273.0296 | L31: 20 | M31: 1 | N31: =1+6*L31/(L31+2000)+M31 -> 2.0594059 | O31: 0 | P31: 0.93 | Q31: 2.3 | R31: =1+P31*Q31 -> 3.139 | S31: 1.15 | T31: 1 | U31: =(K31*N31+O31)*R31*S31*T31 -> 24332.181
F32: e4 | G32: =189+2604 -> 2793 | H32: 0.8724 | I32: 1.28 | J32: =17*0.015+1 -> 1.255 | K32: =G32*H32*I32*J32 -> 3914.1754 | L32: 20 | M32: 1 | N32: =1+6*L32/(L32+2000)+M32 -> 2.0594059 | O32: 0 | P32: 0.93 | Q32: 2.3 | R32: =1+P32*Q32 -> 3.139 | S32: 1.15 | T32: 1 | U32: =(K32*N32+O32)*R32*S32*T32 -> 29098.554
F33: e5 | G33: =189+2604 -> 2793 | H33: 0.7295 | I33: 1.28 | J33: =17*0.015+1 -> 1.255 | K33: =G33*H33*I33*J33 -> 3273.0296 | L33: 20 | M33: 1 | N33: =1+6*L33/(L33+2000)+M33 -> 2.0594059 | O33: 0 | P33: 0.93 | Q33: 2.3 | R33: =1+P33*Q33 -> 3.139 | S33: 1.15 | T33: 1 | U33: =(K33*N33+O33)*R33*S33*T33 -> 24332.181
F34: e6 | G34: =189+2604 -> 2793 | H34: 0.8724 | I34: 1.28 | J34: =17*0.015+1 -> 1.255 | K34: =G34*H34*I34*J34 -> 3914.1754 | L34: 20 | M34: 1 | N34: =1+6*L34/(L34+2000)+M34 -> 2.0594059 | O34: 0 | P34: 0.93 | Q34: 2.3 | R34: =1+P34*Q34 -> 3.139 | S34: 1.15 | T34: 1 | U34: =(K34*N34+O34)*R34*S34*T34 -> 29098.554
F35: e7 | G35: =189+2604 -> 2793 | H35: 0.7295 | I35: 1.28 | J35: =17*0.015+1 -> 1.255 | K35: =G35*H35*I35*J35 -> 3273.0296 | L35: 20 | M35: 1 | N35: =1+6*L35/(L35+2000)+M35 -> 2.0594059 | O35: 0 | P35: 0.93 | Q35: 2.3 | R35: =1+P35*Q35 -> 3.139 | S35: 0.9 | T35: 1 | U35: =(K35*N35+O35)*R35*S35*T35 -> 19042.577
F36: e8 | G36: =189+2604 -> 2793 | H36: 0.8724 | I36: 1.28 | J36: =17*0.015+1 -> 1.255 | K36: =G36*H36*I36*J36 -> 3914.1754 | L36: 20 | M36: 1 | N36: =1+6*L36/(L36+2000)+M36 -> 2.0594059 | O36: 0 | P36: 0.93 | Q36: 2.3 | R36: =1+P36*Q36 -> 3.139 | S36: 0.9 | T36: 1 | U36: =(K36*N36+O36)*R36*S36*T36 -> 22772.781
F37: e9 | G37: 2604 | H37: 0.7295 | I37: 1.28 | J37: 1.24 | K37: =G37*H37*I37*J37 -> 3015.0737 | L37: 20 | M37: 0.5 | N37: =1+6*L37/(L37+2000)+M37 -> 1.5594059 | O37: 0 | P37: 0.93 | Q37: 2.3 | R37: =1+P37*Q37 -> 3.139 | S37: 0.9 | T37: 1 | U37: =(K37*N37+O37)*R37*S37*T37 -> 13282.84
G39: 攻击力 | H39: 倍率 | I39: 独立 | J39: 独立 | K39: 基础乘区 | L39: 冰增伤 | M39: 暴击率 | N39: 爆伤 | O39: 暴击乘区 | P39: 抗性系数 | Q39: 单次伤害 | R39: 次数 | S39: 单总伤 | T39: 总伤
G40: =G28 -> 2604 | H40: 1.9454 | I40: 1 | J40: 1 | K40: =G40*H40*I40*J40 -> 5065.8216 | L40: 1 | M40: 0.93 | N40: 2.3 | O40: =1+M40*N40 -> 3.139 | P40: 0.9 | Q40: =K40*L40*O40*P40 -> 14311.453 | R40: 1 | S40: =Q40*R40 -> 14311.453 | T40: =SUM(S40:S41) -> 136818.63
G41: =G32 -> 2793 | H41: 1.7251 | I41: 1 | J41: 1 | K41: =G41*H41*I41*J41 -> 4818.2043 | L41: 1 | M41: 0.93 | N41: 2.3 | O41: =1+M41*N41 -> 3.139 | P41: 0.9 | Q41: =K41*L41*O41*P41 -> 13611.909 | R41: 9 | S41: =Q41*R41 -> 122507.18
F43: 冰涡
G44: 反应系数 | H44: 冰系数 | I44: 基础系数 | J44: 精通 | K44: 星扩增 | L44: 精通乘区 | M44: 暴击率 | N44: 爆伤 | O44: 暴击乘区 | P44: 抗性系数 | Q44: 擢升 | R44: 权重 | S44: xp伤害 | T44: 触发次数 | U44: 总伤
F45: p1 | G45: 1446.85 | H45: 2 | I45: 1.28 | J45: 200 | K45: 2.08 | L45: =1+6*J45/(J45+2000)+K45 -> 3.6254545 | M45: 0.85 | N45: 2.22 | O45: =1+M45*N45 -> 2.887 | P45: 1.15 | Q45: 1 | R45: 0.6 | S45: =G45*H45*I45*L45*O45*P45*Q45*R45 -> 26749.878 | T45: 2 | U45: =T47*T45 -> 67291.972
...

Sheet 1+1桑0奥
A1: 1＋1桑多涅0＋星峰剑奥c6布0七 | F1: mc | G1: 攻击力 | H1: 倍率 | I1: 基础系数 | J1: 独立 | K1: 基础乘区 | L1: 精通 | M1: 星扩增 | N1: 精通乘区 | O1: 羽毛 | P1: 暴击率 | Q1: 爆伤 | R1: 暴击乘区 | S1: 抗性系数 | T1: 擢升 | U1: 单次伤害 | V1: 总伤
A2: 统计 | B2: DMG | C2: DPS | D2: 轴长 | F2: z | G2: =3199+488+203 -> 3890 | H2: 2.4225 | I2: 1.28 | J2: 1 | K2: =G2*H2*I2*J2 -> 12062.112 | L2: 200 | M2: 2.23 | N2: =1+6*L2/(L2+2000)+M2 -> 3.7754545 | O2: 0 | P2: 0.85 | Q2: 2.22 | R2: =1+P2*Q2 -> 2.887 | S2: 1.15 | T2: 1 | U2: =(K2*N2+O2)*R2*S2*T2 -> 151194.93 | V2: =SUM(U2:U16) -> 2568777.2
B3: =B5+B7+B9 -> 3753903.6 | C3: =B3/D3 -> 174600.17 | D3: 21.5 | F3: z | G3: =3199+488+203 -> 3890 | H3: 2.4225 | I3: 1.28 | J3: 1 | K3: =G3*H3*I3*J3 -> 12062.112 | L3: 200 | M3: 2.38 | N3: =1+6*L3/(L3+2000)+M3 -> 3.9254545 | O3: 0 | P3: 0.85 | Q3: 2.22 | R3: =1+P3*Q3 -> 2.887 | S3: 1.15 | T3: 1 | U3: =(K3*N3+O3)*R3*S3*T3 -> 157201.95
B4: 桑多涅总伤 | C4: 占比 | F4: z | G4: =3199+488+203 -> 3890 | H4: 2.4225 | I4: 1.28 | J4: 1 | K4: =G4*H4*I4*J4 -> 12062.112 | L4: 200 | M4: 2.38 | N4: =1+6*L4/(L4+2000)+M4 -> 3.9254545 | O4: 0 | P4: 0.85 | Q4: 2.22 | R4: =1+P4*Q4 -> 2.887 | S4: 1.15 | T4: 1 | U4: =(K4*N4+O4)*R4*S4*T4 -> 157201.95
B5: =V2+T19 -> 2975522.4 | C5: =B5/B3 -> 0.79264753 | F5: z | G5: =3199+488+203 -> 3890 | H5: 2.4225 | I5: 1.28 | J5: 1 | K5: =G5*H5*I5*J5 -> 12062.112 | L5: 200 | M5: 2.38 | N5: =1+6*L5/(L5+2000)+M5 -> 3.9254545 | O5: 0 | P5: 0.85 | Q5: 2.22 | R5: =1+P5*Q5 -> 2.887 | S5: 1.15 | T5: 1 | U5: =(K5*N5+O5)*R5*S5*T5 -> 157201.95
B6: 奥黛塔总伤 | C6: 占比 | F6: z | G6: =3199+488+203 -> 3890 | H6: 2.4225 | I6: 1.28 | J6: 1 | K6: =G6*H6*I6*J6 -> 12062.112 | L6: 200 | M6: 2.38 | N6: =1+6*L6/(L6+2000)+M6 -> 3.9254545 | O6: 0 | P6: 0.85 | Q6: 2.22 | R6: =1+P6*Q6 -> 2.887 | S6: 1.15 | T6: 1 | U6: =(K6*N6+O6)*R6*S6*T6 -> 157201.95
B7: =V27+T39 -> 586299.57 | C7: =B7/B3 -> 0.15618397 | F7: z | G7: =3199+488+203 -> 3890 | H7: 2.4225 | I7: 1.28 | J7: 1 | K7: =G7*H7*I7*J7 -> 12062.112 | L7: 200 | M7: 2.38 | N7: =1+6*L7/(L7+2000)+M7 -> 3.9254545 | O7: 0 | P7: 0.85 | Q7: 2.22 | R7: =1+P7*Q7 -> 2.887 | S7: 1.15 | T7: 1 | U7: =(K7*N7+O7)*R7*S7*T7 -> 157201.95
B8: 反应伤害 | C8: 占比 | F8: q | G8: =3199+488+203 -> 3890 | H8: 5.9544 | I8: 1.28 | J8: 2 | K8: =G8*H8*I8*J8 -> 59296.297 | L8: 200 | M8: 2.38 | N8: =1+6*L8/(L8+2000)+M8 -> 3.9254545 | O8: 0 | P8: 0.85 | Q8: 2.22 | R8: =1+P8*Q8 -> 2.887 | S8: 1.15 | T8: 1 | U8: =(K8*N8+O8)*R8*S8*T8 -> 772791.17
B9: =U44+U50+U56+U62 -> 192081.61 | C9: =B9/B3 -> 0.051168498 | F9: e | G9: =3199+488+203 -> 3890 | H9: 0.5832 | I9: 1.28 | J9: 4 | K9: =G9*H9*I9*J9 -> 11615.478 | L9: 200 | M9: 2.38 | N9: =1+6*L9/(L9+2000)+M9 -> 3.9254545 | O9: 0 | P9: 0.85 | Q9: 2.22 | R9: =1+P9*Q9 -> 2.887 | S9: 1.15 | T9: 1 | U9: =(K9*N9+O9)*R9*S9*T9 -> 151381.1
F10: z | G10: =3199+488+203 -> 3890 | H10: 2.4225 | I10: 1.28 | J10: 1 | K10: =G10*H10*I10*J10 -> 12062.112 | L10: 200 | M10: 2.38 | N10: =1+6*L10/(L10+2000)+M10 -> 3.9254545 | O10: 0 | P10: 0.85 | Q10: 2.22 | R10: =1+P10*Q10 -> 2.887 | S10: 0.9 | T10: 1 | U10: =(K10*N10+O10)*R10*S10*T10 -> 123027.61
F11: z | G11: =3199+203 -> 3402 | H11: 2.4225 | I11: 1.28 | J11: 1 | K11: =G11*H11*I11*J11 -> 10548.922 | L11: 200 | M11: 2.38 | N11: =1+6*L11/(L11+2000)+M11 -> 3.9254545 | O11: 0 | P11: 0.85 | Q11: 2.22 | R11: =1+P11*Q11 -> 2.887 | S11: 0.9 | T11: 1 | U11: =(K11*N11+O11)*R11*S11*T11 -> 107593.82
F12: z | G12: =3199+203 -> 3402 | H12: 2.4225 | I12: 1.28 | J12: 1 | K12: =G12*H12*I12*J12 -> 10548.922 | L12: 200 | M12: 2.38 | N12: =1+6*L12/(L12+2000)+M12 -> 3.9254545 | O12: 0 | P12: 0.85 | Q12: 2.22 | R12: =1+P12*Q12 -> 2.887 | S12: 0.9 | T12: 1 | U12: =(K12*N12+O12)*R12*S12*T12 -> 107593.82
F13: z | G13: =3199+203 -> 3402 | H13: 2.4225 | I13: 1.28 | J13: 1 | K13: =G13*H13*I13*J13 -> 10548.922 | L13: 200 | M13: 2.38 | N13: =1+6*L13/(L13+2000)+M13 -> 3.9254545 | O13: 0 | P13: 0.85 | Q13: 2.22 | R13: =1+P13*Q13 -> 2.887 | S13: 0.9 | T13: 1 | U13: =(K13*N13+O13)*R13*S13*T13 -> 107593.82
F14: z | G14: =3199 -> 3199 | H14: 2.4225 | I14: 1.28 | J14: 1 | K14: =G14*H14*I14*J14 -> 9919.4592 | L14: 200 | M14: 1.88 | N14: =1+6*L14/(L14+2000)+M14 -> 3.4254545 | O14: 0 | P14: 0.85 | Q14: 2.22 | R14: =1+P14*Q14 -> 2.887 | S14: 0.9 | T14: 1 | U14: =(K14*N14+O14)*R14*S14*T14 -> 88286.743
F15: z | G15: =3199 -> 3199 | H15: 2.4225 | I15: 1.28 | J15: 1 | K15: =G15*H15*I15*J15 -> 9919.4592 | L15: 200 | M15: 1.88 | N15: =1+6*L15/(L15+2000)+M15 -> 3.4254545 | O15: 0 | P15: 0.85 | Q15: 2.22 | R15: =1+P15*Q15 -> 2.887 | S15: 0.9 | T15: 1 | U15: =(K15*N15+O15)*R15*S15*T15 -> 88286.743
F16: e | G16: =3199 -> 3199 | H16: 0.5832 | I16: 1.28 | J16: 4 | K16: =G16*H16*I16*J16 -> 9552.1628 | L16: 200 | M16: 1.88 | N16: =1+6*L16/(L16+2000)+M16 -> 3.4254545 | O16: 0 | P16: 0.85 | Q16: 2.22 | R16: =1+P16*Q16 -> 2.887 | S16: 0.9 | T16: 1 | U16: =(K16*N16+O16)*R16*S16*T16 -> 85017.674
G18: 攻击力 | H18: 倍率 | I18: 独立 | J18: 独立 | K18: 基础乘区 | L18: 冰增伤 | M18: 暴击率 | N18: 爆伤 | O18: 暴击乘区 | P18: 抗性系数 | Q18: 单次伤害 | R18: 次数 | S18: 单总伤 | T18: 总伤
G19: =3199+488+203 -> 3890 | H19: 0.85 | I19: 1 | J19: 1 | K19: =G19*H19*I19*J19 -> 3306.5 | L19: 1 | M19: 0.85 | N19: 2.22 | O19: =1+M19*N19 -> 2.887 | P19: 1.15 | Q19: =K19*L19*O19*P19 -> 10977.745 | R19: 18 | S19: =Q19*R19 -> 197599.42 | T19: =SUM(S19:S25) -> 406745.21
G20: =3199+488+203 -> 3890 | H20: 1.5879 | I20: 3 | J20: 1 | K20: =G20*H20*I20*J20 -> 18530.793 | L20: 1 | M20: 0.85 | N20: 2.22 | O20: =1+M20*N20 -> 2.887 | P20: 1.15 | Q20: =K20*L20*O20*P20 -> 61523.159 | R20: 1 | S20: =Q20*R20 -> 61523.159
G21: =3199+488+203 -> 3890 | H21: 0.5832 | I21: 1 | J21: 1 | K21: =G21*H21*I21*J21 -> 2268.648 | L21: 1 | M21: 0.85 | N21: 2.22 | O21: =1+M21*N21 -> 2.887 | P21: 1.15 | Q21: =K21*L21*O21*P21 -> 7532.0248 | R21: 1 | S21: =Q21*R21 -> 7532.0248
G22: =G11 -> 3402 | H22: 0.85 | I22: 1 | J22: 1 | K22: =G22*H22*I22*J22 -> 2891.7 | L22: 1 | M22: 0.85 | N22: 2.22 | O22: =1+M22*N22 -> 2.887 | P22: 0.9 | Q22: =K22*L22*O22*P22 -> 7513.5041 | R22: 18 | S22: =Q22*R22 -> 135243.07
G23: =G16 -> 3199 | H23: 0.5832 | I23: 1 | J23: 1 | K23: =G23*H23*I23*J23 -> 1865.6568 | L23: 1 | M23: 0.85 | N23: 2.22 | O23: =1+M23*N23 -> 2.887 | P23: 0.9 | Q23: =K23*L23*O23*P23 -> 4847.5361 | R23: 1 | S23: =Q23*R23 -> 4847.5361
F25: 奥黛塔
F26: mc | G26: 攻击力 | H26: 倍率 | I26: 基础系数 | J26: 独立 | K26: 基础乘区 | L26: 精通 | M26: 星扩增 | N26: 精通乘区 | O26: 羽毛 | P26: 暴击率 | Q26: 爆伤 | R26: 暴击乘区 | S26: 抗性系数 | T26: 擢升 | U26: 单次伤害 | V26: 总伤
F27: ee | G27: 2604 | H27: 8.2555 | I27: 1.28 | J27: =16*0.015+1 -> 1.24 | K27: =G27*H27*I27*J27 -> 34120.549 | L27: 20 | M27: 1.1 | N27: =1+6*L27/(L27+2000)+M27 -> 2.1594059 | O27: 0 | P27: 0.93 | Q27: 2.3 | R27: =1+P27*Q27 -> 3.139 | S27: 0.9 | T27: 1 | U27: =(K27*N27+O27)*R27*S27*T27 -> 208153.7 | V27: =SUM(U27:U36) -> 449480.94
F28: e1 | G28: =189+2604 -> 2793 | H28: 0.7295 | I28: 1.28 | J28: =17*0.015+1 -> 1.255 | K28: =G28*H28*I28*J28 -> 3273.0296 | L28: 20 | M28: 1.3 | N28: =1+6*L28/(L28+2000)+M28 -> 2.3594059 | O28: 0 | P28: 0.93 | Q28: 2.3 | R28: =1+P28*Q28 -> 3.139 | S28: 0.9 | T28: 1 | U28: =(K28*N28+O28)*R28*S28*T28 -> 21816.567
F29: e2 | G29: =189+2604 -> 2793 | H29: 0.8724 | I29: 1.28 | J29: =17*0.015+1 -> 1.255 | K29: =G29*H29*I29*J29 -> 3914.1754 | L29: 20 | M29: 1.3 | N29: =1+6*L29/(L29+2000)+M29 -> 2.3594059 | O29: 0 | P29: 0.93 | Q29: 2.3 | R29: =1+P29*Q29 -> 3.139 | S29: 1.15 | T29: 1 | U29: =(K29*N29+O29)*R29*S29*T29 -> 33337.43
F30: e3 | G30: =189+2604 -> 2793 | H30: 0.7295 | I30: 1.28 | J30: =17*0.015+1 -> 1.255 | K30: =G30*H30*I30*J30 -> 3273.0296 | L30: 20 | M30: 1.3 | N30: =1+6*L30/(L30+2000)+M30 -> 2.3594059 | O30: 0 | P30: 0.93 | Q30: 2.3 | R30: =1+P30*Q30 -> 3.139 | S30: 1.15 | T30: 1 | U30: =(K30*N30+O30)*R30*S30*T30 -> 27876.725
F31: e4 | G31: =189+2604 -> 2793 | H31: 0.8724 | I31: 1.28 | J31: =17*0.015+1 -> 1.255 | K31: =G31*H31*I31*J31 -> 3914.1754 | L31: 20 | M31: 1.3 | N31: =1+6*L31/(L31+2000)+M31 -> 2.3594059 | O31: 0 | P31: 0.93 | Q31: 2.3 | R31: =1+P31*Q31 -> 3.139 | S31: 1.15 | T31: 1 | U31: =(K31*N31+O31)*R31*S31*T31 -> 33337.43
F32: e5 | G32: =189+2604 -> 2793 | H32: 0.7295 | I32: 1.28 | J32: =17*0.015+1 -> 1.255 | K32: =G32*H32*I32*J32 -> 3273.0296 | L32: 20 | M32: 1.3 | N32: =1+6*L32/(L32+2000)+M32 -> 2.3594059 | O32: 0 | P32: 0.93 | Q32: 2.3 | R32: =1+P32*Q32 -> 3.139 | S32: 1.15 | T32: 1 | U32: =(K32*N32+O32)*R32*S32*T32 -> 27876.725
F33: e6 | G33: =189+2604 -> 2793 | H33: 0.8724 | I33: 1.28 | J33: =17*0.015+1 -> 1.255 | K33: =G33*H33*I33*J33 -> 3914.1754 | L33: 20 | M33: 1.3 | N33: =1+6*L33/(L33+2000)+M33 -> 2.3594059 | O33: 0 | P33: 0.93 | Q33: 2.3 | R33: =1+P33*Q33 -> 3.139 | S33: 1.15 | T33: 1 | U33: =(K33*N33+O33)*R33*S33*T33 -> 33337.43
F34: e7 | G34: =189+2604 -> 2793 | H34: 0.7295 | I34: 1.28 | J34: =17*0.015+1 -> 1.255 | K34: =G34*H34*I34*J34 -> 3273.0296 | L34: 20 | M34: 1.3 | N34: =1+6*L34/(L34+2000)+M34 -> 2.3594059 | O34: 0 | P34: 0.93 | Q34: 2.3 | R34: =1+P34*Q34 -> 3.139 | S34: 0.9 | T34: 1 | U34: =(K34*N34+O34)*R34*S34*T34 -> 21816.567
F35: e8 | G35: =189+2604 -> 2793 | H35: 0.8724 | I35: 1.28 | J35: =17*0.015+1 -> 1.255 | K35: =G35*H35*I35*J35 -> 3914.1754 | L35: 20 | M35: 1.3 | N35: =1+6*L35/(L35+2000)+M35 -> 2.3594059 | O35: 0 | P35: 0.93 | Q35: 2.3 | R35: =1+P35*Q35 -> 3.139 | S35: 0.9 | T35: 1 | U35: =(K35*N35+O35)*R35*S35*T35 -> 26090.162
F36: e9 | G36: 2604 | H36: 0.7295 | I36: 1.28 | J36: 1.24 | K36: =G36*H36*I36*J36 -> 3015.0737 | L36: 20 | M36: 0.8 | N36: =1+6*L36/(L36+2000)+M36 -> 1.8594059 | O36: 0 | P36: 0.93 | Q36: 2.3 | R36: =1+P36*Q36 -> 3.139 | S36: 0.9 | T36: 1 | U36: =(K36*N36+O36)*R36*S36*T36 -> 15838.205
G38: 攻击力 | H38: 倍率 | I38: 独立 | J38: 独立 | K38: 基础乘区 | L38: 冰增伤 | M38: 暴击率 | N38: 爆伤 | O38: 暴击乘区 | P38: 抗性系数 | Q38: 单次伤害 | R38: 次数 | S38: 单总伤 | T38: 总伤
G39: =G27 -> 2604 | H39: 1.9454 | I39: 1 | J39: 1 | K39: =G39*H39*I39*J39 -> 5065.8216 | L39: 1 | M39: 0.93 | N39: 2.3 | O39: =1+M39*N39 -> 3.139 | P39: 0.9 | Q39: =K39*L39*O39*P39 -> 14311.453 | R39: 1 | S39: =Q39*R39 -> 14311.453 | T39: =SUM(S39:S40) -> 136818.63
G40: =G31 -> 2793 | H40: 1.7251 | I40: 1 | J40: 1 | K40: =G40*H40*I40*J40 -> 4818.2043 | L40: 1 | M40: 0.93 | N40: 2.3 | O40: =1+M40*N40 -> 3.139 | P40: 0.9 | Q40: =K40*L40*O40*P40 -> 13611.909 | R40: 9 | S40: =Q40*R40 -> 122507.18
F42: 冰涡
G43: 反应系数 | H43: 冰系数 | I43: 基础系数 | J43: 精通 | K43: 星扩增 | L43: 精通乘区 | M43: 暴击率 | N43: 爆伤 | O43: 暴击乘区 | P43: 抗性系数 | Q43: 擢升 | R43: 权重 | S43: xp伤害 | T43: 触发次数 | U43: 总伤
F44: p1 | G44: 1446.85 | H44: 2 | I44: 1.28 | J44: 200 | K44: 2.38 | L44: =1+6*J44/(J44+2000)+K44 -> 3.9254545 | M44: 0.85 | N44: 2.22 | O44: =1+M44*N44 -> 2.887 | P44: 1.15 | Q44: 1 | R44: 0.6 | S44: =G44*H44*I44*L44*O44*P44*Q44*R44 -> 28963.384 | T44: 2 | U44: =T46*T44 -> 73393.794
...

Sheet 2+1桑0奥 
A1: 2＋1桑多涅0＋星峰剑奥c6布0七 | F1: mc | G1: 攻击力 | H1: 倍率 | I1: 基础系数 | J1: 独立 | K1: 基础乘区 | L1: 精通 | M1: 星扩增 | N1: 精通乘区 | O1: 羽毛 | P1: 暴击率 | Q1: 爆伤 | R1: 暴击乘区 | S1: 抗性系数 | T1: 擢升 | U1: 单次伤害 | V1: 总伤
A2: 统计 | B2: DMG | C2: DPS | D2: 轴长 | F2: z | G2: =3199+488+203 -> 3890 | H2: 2.4225 | I2: 1.28 | J2: 1 | K2: =G2*H2*I2*J2 -> 12062.112 | L2: 200 | M2: 2.23 | N2: =1+6*L2/(L2+2000)+M2 -> 3.7754545 | O2: 0 | P2: 0.85 | Q2: 2.62 | R2: =1+P2*Q2 -> 3.227 | S2: 1.15 | T2: 1 | U2: =(K2*N2+O2)*R2*S2*T2 -> 169001.05 | V2: =SUM(U2:U16) -> 2932736.2
B3: =B5+B7+B9 -> 4117862.6 | C3: =B3/D3 -> 191528.49 | D3: 21.5 | F3: z | G3: =3199+488+203 -> 3890 | H3: 2.4225 | I3: 1.28 | J3: 1 | K3: =G3*H3*I3*J3 -> 12062.112 | L3: 200 | M3: 2.38 | N3: =1+6*L3/(L3+2000)+M3 -> 3.9254545 | O3: 0 | P3: 0.85 | Q3: 2.82 | R3: =1+P3*Q3 -> 3.397 | S3: 1.15 | T3: 1 | U3: =(K3*N3+O3)*R3*S3*T3 -> 184972.3
B4: 桑多涅总伤 | C4: 占比 | F4: z | G4: =3199+488+203 -> 3890 | H4: 2.4225 | I4: 1.28 | J4: 1 | K4: =G4*H4*I4*J4 -> 12062.112 | L4: 200 | M4: 2.38 | N4: =1+6*L4/(L4+2000)+M4 -> 3.9254545 | O4: 0 | P4: 0.85 | Q4: 3.02 | R4: =1+P4*Q4 -> 3.567 | S4: 1.15 | T4: 1 | U4: =(K4*N4+O4)*R4*S4*T4 -> 194229.08
B5: =V2+T19 -> 3339481.5 | C5: =B5/B3 -> 0.81097447 | F5: z | G5: =3199+488+203 -> 3890 | H5: 2.4225 | I5: 1.28 | J5: 1 | K5: =G5*H5*I5*J5 -> 12062.112 | L5: 200 | M5: 2.38 | N5: =1+6*L5/(L5+2000)+M5 -> 3.9254545 | O5: 0 | P5: 0.85 | Q5: 3.22 | R5: =1+P5*Q5 -> 3.737 | S5: 1.15 | T5: 1 | U5: =(K5*N5+O5)*R5*S5*T5 -> 203485.87
B6: 奥黛塔总伤 | C6: 占比 | F6: z | G6: =3199+488+203 -> 3890 | H6: 2.4225 | I6: 1.28 | J6: 1 | K6: =G6*H6*I6*J6 -> 12062.112 | L6: 200 | M6: 2.38 | N6: =1+6*L6/(L6+2000)+M6 -> 3.9254545 | O6: 0 | P6: 0.85 | Q6: 3.22 | R6: =1+P6*Q6 -> 3.737 | S6: 1.15 | T6: 1 | U6: =(K6*N6+O6)*R6*S6*T6 -> 203485.87
B7: =V27+T39 -> 586299.57 | C7: =B7/B3 -> 0.14237959 | F7: z | G7: =3199+488+203 -> 3890 | H7: 2.4225 | I7: 1.28 | J7: 1 | K7: =G7*H7*I7*J7 -> 12062.112 | L7: 200 | M7: 2.38 | N7: =1+6*L7/(L7+2000)+M7 -> 3.9254545 | O7: 0 | P7: 0.85 | Q7: 3.22 | R7: =1+P7*Q7 -> 3.737 | S7: 1.15 | T7: 1 | U7: =(K7*N7+O7)*R7*S7*T7 -> 203485.87
B8: 反应伤害 | C8: 占比 | F8: q | G8: =3199+488+203 -> 3890 | H8: 5.9544 | I8: 1.28 | J8: 2 | K8: =G8*H8*I8*J8 -> 59296.297 | L8: 200 | M8: 2.38 | N8: =1+6*L8/(L8+2000)+M8 -> 3.9254545 | O8: 0 | P8: 0.85 | Q8: 2.22 | R8: =1+P8*Q8 -> 2.887 | S8: 1.15 | T8: 1 | U8: =(K8*N8+O8)*R8*S8*T8 -> 772791.17
B9: =U44+U50+U56+U62 -> 192081.61 | C9: =B9/B3 -> 0.046645948 | F9: e | G9: =3199+488+203 -> 3890 | H9: 0.5832 | I9: 1.28 | J9: 4 | K9: =G9*H9*I9*J9 -> 11615.478 | L9: 200 | M9: 2.38 | N9: =1+6*L9/(L9+2000)+M9 -> 3.9254545 | O9: 0 | P9: 0.85 | Q9: 2.22 | R9: =1+P9*Q9 -> 2.887 | S9: 1.15 | T9: 1 | U9: =(K9*N9+O9)*R9*S9*T9 -> 151381.1
F10: z | G10: =3199+488+203 -> 3890 | H10: 2.4225 | I10: 1.28 | J10: 1 | K10: =G10*H10*I10*J10 -> 12062.112 | L10: 200 | M10: 2.38 | N10: =1+6*L10/(L10+2000)+M10 -> 3.9254545 | O10: 0 | P10: 0.85 | Q10: 2.62 | R10: =1+P10*Q10 -> 3.227 | S10: 0.9 | T10: 1 | U10: =(K10*N10+O10)*R10*S10*T10 -> 137516.49
F11: z | G11: =3199+203 -> 3402 | H11: 2.4225 | I11: 1.28 | J11: 1 | K11: =G11*H11*I11*J11 -> 10548.922 | L11: 200 | M11: 2.38 | N11: =1+6*L11/(L11+2000)+M11 -> 3.9254545 | O11: 0 | P11: 0.85 | Q11: 2.82 | R11: =1+P11*Q11 -> 3.397 | S11: 0.9 | T11: 1 | U11: =(K11*N11+O11)*R11*S11*T11 -> 126600.69
F12: z | G12: =3199+203 -> 3402 | H12: 2.4225 | I12: 1.28 | J12: 1 | K12: =G12*H12*I12*J12 -> 10548.922 | L12: 200 | M12: 2.38 | N12: =1+6*L12/(L12+2000)+M12 -> 3.9254545 | O12: 0 | P12: 0.85 | Q12: 3.02 | R12: =1+P12*Q12 -> 3.567 | S12: 0.9 | T12: 1 | U12: =(K12*N12+O12)*R12*S12*T12 -> 132936.32
F13: z | G13: =3199+203 -> 3402 | H13: 2.4225 | I13: 1.28 | J13: 1 | K13: =G13*H13*I13*J13 -> 10548.922 | L13: 200 | M13: 2.38 | N13: =1+6*L13/(L13+2000)+M13 -> 3.9254545 | O13: 0 | P13: 0.85 | Q13: 3.22 | R13: =1+P13*Q13 -> 3.737 | S13: 0.9 | T13: 1 | U13: =(K13*N13+O13)*R13*S13*T13 -> 139271.94
F14: z | G14: =3199 -> 3199 | H14: 2.4225 | I14: 1.28 | J14: 1 | K14: =G14*H14*I14*J14 -> 9919.4592 | L14: 200 | M14: 1.88 | N14: =1+6*L14/(L14+2000)+M14 -> 3.4254545 | O14: 0 | P14: 0.85 | Q14: 3.22 | R14: =1+P14*Q14 -> 3.737 | S14: 0.9 | T14: 1 | U14: =(K14*N14+O14)*R14*S14*T14 -> 114280.42
F15: z | G15: =3199 -> 3199 | H15: 2.4225 | I15: 1.28 | J15: 1 | K15: =G15*H15*I15*J15 -> 9919.4592 | L15: 200 | M15: 1.88 | N15: =1+6*L15/(L15+2000)+M15 -> 3.4254545 | O15: 0 | P15: 0.85 | Q15: 3.22 | R15: =1+P15*Q15 -> 3.737 | S15: 0.9 | T15: 1 | U15: =(K15*N15+O15)*R15*S15*T15 -> 114280.42
F16: e | G16: =3199 -> 3199 | H16: 0.5832 | I16: 1.28 | J16: 4 | K16: =G16*H16*I16*J16 -> 9552.1628 | L16: 200 | M16: 1.88 | N16: =1+6*L16/(L16+2000)+M16 -> 3.4254545 | O16: 0 | P16: 0.85 | Q16: 2.22 | R16: =1+P16*Q16 -> 2.887 | S16: 0.9 | T16: 1 | U16: =(K16*N16+O16)*R16*S16*T16 -> 85017.674
G18: 攻击力 | H18: 倍率 | I18: 独立 | J18: 独立 | K18: 基础乘区 | L18: 冰增伤 | M18: 暴击率 | N18: 爆伤 | O18: 暴击乘区 | P18: 抗性系数 | Q18: 单次伤害 | R18: 次数 | S18: 单总伤 | T18: 总伤
G19: =3199+488+203 -> 3890 | H19: 0.85 | I19: 1 | J19: 1 | K19: =G19*H19*I19*J19 -> 3306.5 | L19: 1 | M19: 0.85 | N19: 2.22 | O19: =1+M19*N19 -> 2.887 | P19: 1.15 | Q19: =K19*L19*O19*P19 -> 10977.745 | R19: 18 | S19: =Q19*R19 -> 197599.42 | T19: =SUM(S19:S25) -> 406745.21
G20: =3199+488+203 -> 3890 | H20: 1.5879 | I20: 3 | J20: 1 | K20: =G20*H20*I20*J20 -> 18530.793 | L20: 1 | M20: 0.85 | N20: 2.22 | O20: =1+M20*N20 -> 2.887 | P20: 1.15 | Q20: =K20*L20*O20*P20 -> 61523.159 | R20: 1 | S20: =Q20*R20 -> 61523.159
G21: =3199+488+203 -> 3890 | H21: 0.5832 | I21: 1 | J21: 1 | K21: =G21*H21*I21*J21 -> 2268.648 | L21: 1 | M21: 0.85 | N21: 2.22 | O21: =1+M21*N21 -> 2.887 | P21: 1.15 | Q21: =K21*L21*O21*P21 -> 7532.0248 | R21: 1 | S21: =Q21*R21 -> 7532.0248
G22: =G11 -> 3402 | H22: 0.85 | I22: 1 | J22: 1 | K22: =G22*H22*I22*J22 -> 2891.7 | L22: 1 | M22: 0.85 | N22: 2.22 | O22: =1+M22*N22 -> 2.887 | P22: 0.9 | Q22: =K22*L22*O22*P22 -> 7513.5041 | R22: 18 | S22: =Q22*R22 -> 135243.07
G23: =G16 -> 3199 | H23: 0.5832 | I23: 1 | J23: 1 | K23: =G23*H23*I23*J23 -> 1865.6568 | L23: 1 | M23: 0.85 | N23: 2.22 | O23: =1+M23*N23 -> 2.887 | P23: 0.9 | Q23: =K23*L23*O23*P23 -> 4847.5361 | R23: 1 | S23: =Q23*R23 -> 4847.5361
F25: 奥黛塔
F26: mc | G26: 攻击力 | H26: 倍率 | I26: 基础系数 | J26: 独立 | K26: 基础乘区 | L26: 精通 | M26: 星扩增 | N26: 精通乘区 | O26: 羽毛 | P26: 暴击率 | Q26: 爆伤 | R26: 暴击乘区 | S26: 抗性系数 | T26: 擢升 | U26: 单次伤害 | V26: 总伤
F27: ee | G27: 2604 | H27: 8.2555 | I27: 1.28 | J27: =16*0.015+1 -> 1.24 | K27: =G27*H27*I27*J27 -> 34120.549 | L27: 20 | M27: 1.1 | N27: =1+6*L27/(L27+2000)+M27 -> 2.1594059 | O27: 0 | P27: 0.93 | Q27: 2.3 | R27: =1+P27*Q27 -> 3.139 | S27: 0.9 | T27: 1 | U27: =(K27*N27+O27)*R27*S27*T27 -> 208153.7 | V27: =SUM(U27:U36) -> 449480.94
F28: e1 | G28: =189+2604 -> 2793 | H28: 0.7295 | I28: 1.28 | J28: =17*0.015+1 -> 1.255 | K28: =G28*H28*I28*J28 -> 3273.0296 | L28: 20 | M28: 1.3 | N28: =1+6*L28/(L28+2000)+M28 -> 2.3594059 | O28: 0 | P28: 0.93 | Q28: 2.3 | R28: =1+P28*Q28 -> 3.139 | S28: 0.9 | T28: 1 | U28: =(K28*N28+O28)*R28*S28*T28 -> 21816.567
F29: e2 | G29: =189+2604 -> 2793 | H29: 0.8724 | I29: 1.28 | J29: =17*0.015+1 -> 1.255 | K29: =G29*H29*I29*J29 -> 3914.1754 | L29: 20 | M29: 1.3 | N29: =1+6*L29/(L29+2000)+M29 -> 2.3594059 | O29: 0 | P29: 0.93 | Q29: 2.3 | R29: =1+P29*Q29 -> 3.139 | S29: 1.15 | T29: 1 | U29: =(K29*N29+O29)*R29*S29*T29 -> 33337.43
F30: e3 | G30: =189+2604 -> 2793 | H30: 0.7295 | I30: 1.28 | J30: =17*0.015+1 -> 1.255 | K30: =G30*H30*I30*J30 -> 3273.0296 | L30: 20 | M30: 1.3 | N30: =1+6*L30/(L30+2000)+M30 -> 2.3594059 | O30: 0 | P30: 0.93 | Q30: 2.3 | R30: =1+P30*Q30 -> 3.139 | S30: 1.15 | T30: 1 | U30: =(K30*N30+O30)*R30*S30*T30 -> 27876.725
F31: e4 | G31: =189+2604 -> 2793 | H31: 0.8724 | I31: 1.28 | J31: =17*0.015+1 -> 1.255 | K31: =G31*H31*I31*J31 -> 3914.1754 | L31: 20 | M31: 1.3 | N31: =1+6*L31/(L31+2000)+M31 -> 2.3594059 | O31: 0 | P31: 0.93 | Q31: 2.3 | R31: =1+P31*Q31 -> 3.139 | S31: 1.15 | T31: 1 | U31: =(K31*N31+O31)*R31*S31*T31 -> 33337.43
F32: e5 | G32: =189+2604 -> 2793 | H32: 0.7295 | I32: 1.28 | J32: =17*0.015+1 -> 1.255 | K32: =G32*H32*I32*J32 -> 3273.0296 | L32: 20 | M32: 1.3 | N32: =1+6*L32/(L32+2000)+M32 -> 2.3594059 | O32: 0 | P32: 0.93 | Q32: 2.3 | R32: =1+P32*Q32 -> 3.139 | S32: 1.15 | T32: 1 | U32: =(K32*N32+O32)*R32*S32*T32 -> 27876.725
F33: e6 | G33: =189+2604 -> 2793 | H33: 0.8724 | I33: 1.28 | J33: =17*0.015+1 -> 1.255 | K33: =G33*H33*I33*J33 -> 3914.1754 | L33: 20 | M33: 1.3 | N33: =1+6*L33/(L33+2000)+M33 -> 2.3594059 | O33: 0 | P33: 0.93 | Q33: 2.3 | R33: =1+P33*Q33 -> 3.139 | S33: 1.15 | T33: 1 | U33: =(K33*N33+O33)*R33*S33*T33 -> 33337.43
F34: e7 | G34: =189+2604 -> 2793 | H34: 0.7295 | I34: 1.28 | J34: =17*0.015+1 -> 1.255 | K34: =G34*H34*I34*J34 -> 3273.0296 | L34: 20 | M34: 1.3 | N34: =1+6*L34/(L34+2000)+M34 -> 2.3594059 | O34: 0 | P34: 0.93 | Q34: 2.3 | R34: =1+P34*Q34 -> 3.139 | S34: 0.9 | T34: 1 | U34: =(K34*N34+O34)*R34*S34*T34 -> 21816.567
F35: e8 | G35: =189+2604 -> 2793 | H35: 0.8724 | I35: 1.28 | J35: =17*0.015+1 -> 1.255 | K35: =G35*H35*I35*J35 -> 3914.1754 | L35: 20 | M35: 1.3 | N35: =1+6*L35/(L35+2000)+M35 -> 2.3594059 | O35: 0 | P35: 0.93 | Q35: 2.3 | R35: =1+P35*Q35 -> 3.139 | S35: 0.9 | T35: 1 | U35: =(K35*N35+O35)*R35*S35*T35 -> 26090.162
F36: e9 | G36: 2604 | H36: 0.7295 | I36: 1.28 | J36: 1.24 | K36: =G36*H36*I36*J36 -> 3015.0737 | L36: 20 | M36: 0.8 | N36: =1+6*L36/(L36+2000)+M36 -> 1.8594059 | O36: 0 | P36: 0.93 | Q36: 2.3 | R36: =1+P36*Q36 -> 3.139 | S36: 0.9 | T36: 1 | U36: =(K36*N36+O36)*R36*S36*T36 -> 15838.205
G38: 攻击力 | H38: 倍率 | I38: 独立 | J38: 独立 | K38: 基础乘区 | L38: 冰增伤 | M38: 暴击率 | N38: 爆伤 | O38: 暴击乘区 | P38: 抗性系数 | Q38: 单次伤害 | R38: 次数 | S38: 单总伤 | T38: 总伤
G39: =G27 -> 2604 | H39: 1.9454 | I39: 1 | J39: 1 | K39: =G39*H39*I39*J39 -> 5065.8216 | L39: 1 | M39: 0.93 | N39: 2.3 | O39: =1+M39*N39 -> 3.139 | P39: 0.9 | Q39: =K39*L39*O39*P39 -> 14311.453 | R39: 1 | S39: =Q39*R39 -> 14311.453 | T39: =SUM(S39:S40) -> 136818.63
G40: =G31 -> 2793 | H40: 1.7251 | I40: 1 | J40: 1 | K40: =G40*H40*I40*J40 -> 4818.2043 | L40: 1 | M40: 0.93 | N40: 2.3 | O40: =1+M40*N40 -> 3.139 | P40: 0.9 | Q40: =K40*L40*O40*P40 -> 13611.909 | R40: 9 | S40: =Q40*R40 -> 122507.18
F42: 冰涡
G43: 反应系数 | H43: 冰系数 | I43: 基础系数 | J43: 精通 | K43: 星扩增 | L43: 精通乘区 | M43: 暴击率 | N43: 爆伤 | O43: 暴击乘区 | P43: 抗性系数 | Q43: 擢升 | R43: 权重 | S43: xp伤害 | T43: 触发次数 | U43: 总伤
F44: p1 | G44: 1446.85 | H44: 2 | I44: 1.28 | J44: 200 | K44: 2.38 | L44: =1+6*J44/(J44+2000)+K44 -> 3.9254545 | M44: 0.85 | N44: 2.22 | O44: =1+M44*N44 -> 2.887 | P44: 1.15 | Q44: 1 | R44: 0.6 | S44: =G44*H44*I44*L44*O44*P44*Q44*R44 -> 28963.384 | T44: 2 | U44: =T46*T44 -> 73393.794
...

Sheet 3+1桑0奥 
A1: 3＋1桑多涅0＋星峰剑奥c6布0七 | F1: mc | G1: 攻击力 | H1: 倍率 | I1: 基础系数 | J1: 独立 | K1: 基础乘区 | L1: 精通 | M1: 星扩增 | N1: 精通乘区 | O1: 羽毛 | P1: 暴击率 | Q1: 爆伤 | R1: 暴击乘区 | S1: 抗性系数 | T1: 擢升 | U1: 单次伤害 | V1: 总伤
A2: 统计 | B2: DMG | C2: DPS | D2: 轴长 | F2: z | G2: =3199+488+203 -> 3890 | H2: 2.9355 | I2: 1.28 | J2: 1 | K2: =G2*H2*I2*J2 -> 14616.442 | L2: 200 | M2: 2.23 | N2: =1+6*L2/(L2+2000)+M2 -> 3.7754545 | O2: 0 | P2: 0.85 | Q2: 2.62 | R2: =1+P2*Q2 -> 3.227 | S2: 1.15 | T2: 1 | U2: =(K2*N2+O2)*R2*S2*T2 -> 204789.51 | V2: =SUM(U2:U16) -> 3340075.5
B3: =B5+B7+B9 -> 4595686.1 | C3: =B3/D3 -> 213752.84 | D3: 21.5 | F3: z | G3: =3199+488+203 -> 3890 | H3: 2.9355 | I3: 1.28 | J3: 1 | K3: =G3*H3*I3*J3 -> 14616.442 | L3: 200 | M3: 2.38 | N3: =1+6*L3/(L3+2000)+M3 -> 3.9254545 | O3: 0 | P3: 0.85 | Q3: 2.82 | R3: =1+P3*Q3 -> 3.397 | S3: 1.15 | T3: 1 | U3: =(K3*N3+O3)*R3*S3*T3 -> 224142.9
B4: 桑多涅总伤 | C4: 占比 | F4: z | G4: =3199+488+203 -> 3890 | H4: 2.9355 | I4: 1.28 | J4: 1 | K4: =G4*H4*I4*J4 -> 14616.442 | L4: 200 | M4: 2.38 | N4: =1+6*L4/(L4+2000)+M4 -> 3.9254545 | O4: 0 | P4: 0.85 | Q4: 3.02 | R4: =1+P4*Q4 -> 3.567 | S4: 1.15 | T4: 1 | U4: =(K4*N4+O4)*R4*S4*T4 -> 235359.95
B5: =V2+T19 -> 3817305 | C5: =B5/B3 -> 0.83062786 | F5: z | G5: =3199+488+203 -> 3890 | H5: 2.9355 | I5: 1.28 | J5: 1 | K5: =G5*H5*I5*J5 -> 14616.442 | L5: 200 | M5: 2.38 | N5: =1+6*L5/(L5+2000)+M5 -> 3.9254545 | O5: 0 | P5: 0.85 | Q5: 3.22 | R5: =1+P5*Q5 -> 3.737 | S5: 1.15 | T5: 1 | U5: =(K5*N5+O5)*R5*S5*T5 -> 246576.99
B6: 奥黛塔总伤 | C6: 占比 | F6: z | G6: =3199+488+203 -> 3890 | H6: 2.9355 | I6: 1.28 | J6: 1 | K6: =G6*H6*I6*J6 -> 14616.442 | L6: 200 | M6: 2.38 | N6: =1+6*L6/(L6+2000)+M6 -> 3.9254545 | O6: 0 | P6: 0.85 | Q6: 3.22 | R6: =1+P6*Q6 -> 3.737 | S6: 1.15 | T6: 1 | U6: =(K6*N6+O6)*R6*S6*T6 -> 246576.99
B7: =V27+T39 -> 586299.57 | C7: =B7/B3 -> 0.12757607 | F7: z | G7: =3199+488+203 -> 3890 | H7: 2.9355 | I7: 1.28 | J7: 1 | K7: =G7*H7*I7*J7 -> 14616.442 | L7: 200 | M7: 2.38 | N7: =1+6*L7/(L7+2000)+M7 -> 3.9254545 | O7: 0 | P7: 0.85 | Q7: 3.22 | R7: =1+P7*Q7 -> 3.737 | S7: 1.15 | T7: 1 | U7: =(K7*N7+O7)*R7*S7*T7 -> 246576.99
B8: 反应伤害 | C8: 占比 | F8: q | G8: =3199+488+203 -> 3890 | H8: 5.9544 | I8: 1.28 | J8: 2 | K8: =G8*H8*I8*J8 -> 59296.297 | L8: 200 | M8: 2.38 | N8: =1+6*L8/(L8+2000)+M8 -> 3.9254545 | O8: 0 | P8: 0.85 | Q8: 2.22 | R8: =1+P8*Q8 -> 2.887 | S8: 1.15 | T8: 1 | U8: =(K8*N8+O8)*R8*S8*T8 -> 772791.17
B9: =U44+U50+U56+U62 -> 192081.61 | C9: =B9/B3 -> 0.041796067 | F9: e | G9: =3199+488+203 -> 3890 | H9: 0.5832 | I9: 1.28 | J9: 4 | K9: =G9*H9*I9*J9 -> 11615.478 | L9: 200 | M9: 2.38 | N9: =1+6*L9/(L9+2000)+M9 -> 3.9254545 | O9: 0 | P9: 0.85 | Q9: 2.22 | R9: =1+P9*Q9 -> 2.887 | S9: 1.15 | T9: 1 | U9: =(K9*N9+O9)*R9*S9*T9 -> 151381.1
F10: z | G10: =3199+488+203 -> 3890 | H10: 2.9355 | I10: 1.28 | J10: 1 | K10: =G10*H10*I10*J10 -> 14616.442 | L10: 200 | M10: 2.38 | N10: =1+6*L10/(L10+2000)+M10 -> 3.9254545 | O10: 0 | P10: 0.85 | Q10: 2.62 | R10: =1+P10*Q10 -> 3.227 | S10: 0.9 | T10: 1 | U10: =(K10*N10+O10)*R10*S10*T10 -> 166637.63
F11: z | G11: =3199+203 -> 3402 | H11: 2.9355 | I11: 1.28 | J11: 1 | K11: =G11*H11*I11*J11 -> 12782.811 | L11: 200 | M11: 2.38 | N11: =1+6*L11/(L11+2000)+M11 -> 3.9254545 | O11: 0 | P11: 0.85 | Q11: 2.82 | R11: =1+P11*Q11 -> 3.397 | S11: 0.9 | T11: 1 | U11: =(K11*N11+O11)*R11*S11*T11 -> 153410.25
F12: z | G12: =3199+203 -> 3402 | H12: 2.9355 | I12: 1.28 | J12: 1 | K12: =G12*H12*I12*J12 -> 12782.811 | L12: 200 | M12: 2.38 | N12: =1+6*L12/(L12+2000)+M12 -> 3.9254545 | O12: 0 | P12: 0.85 | Q12: 3.02 | R12: =1+P12*Q12 -> 3.567 | S12: 0.9 | T12: 1 | U12: =(K12*N12+O12)*R12*S12*T12 -> 161087.53
F13: z | G13: =3199+203 -> 3402 | H13: 2.9355 | I13: 1.28 | J13: 1 | K13: =G13*H13*I13*J13 -> 12782.811 | L13: 200 | M13: 2.38 | N13: =1+6*L13/(L13+2000)+M13 -> 3.9254545 | O13: 0 | P13: 0.85 | Q13: 3.22 | R13: =1+P13*Q13 -> 3.737 | S13: 0.9 | T13: 1 | U13: =(K13*N13+O13)*R13*S13*T13 -> 168764.82
F14: z | G14: =3199 -> 3199 | H14: 2.9355 | I14: 1.28 | J14: 1 | K14: =G14*H14*I14*J14 -> 12020.051 | L14: 200 | M14: 1.88 | N14: =1+6*L14/(L14+2000)+M14 -> 3.4254545 | O14: 0 | P14: 0.85 | Q14: 3.22 | R14: =1+P14*Q14 -> 3.737 | S14: 0.9 | T14: 1 | U14: =(K14*N14+O14)*R14*S14*T14 -> 138480.97
F15: z | G15: =3199 -> 3199 | H15: 2.9355 | I15: 1.28 | J15: 1 | K15: =G15*H15*I15*J15 -> 12020.051 | L15: 200 | M15: 1.88 | N15: =1+6*L15/(L15+2000)+M15 -> 3.4254545 | O15: 0 | P15: 0.85 | Q15: 3.22 | R15: =1+P15*Q15 -> 3.737 | S15: 0.9 | T15: 1 | U15: =(K15*N15+O15)*R15*S15*T15 -> 138480.97
F16: e | G16: =3199 -> 3199 | H16: 0.5832 | I16: 1.28 | J16: 4 | K16: =G16*H16*I16*J16 -> 9552.1628 | L16: 200 | M16: 1.88 | N16: =1+6*L16/(L16+2000)+M16 -> 3.4254545 | O16: 0 | P16: 0.85 | Q16: 2.22 | R16: =1+P16*Q16 -> 2.887 | S16: 0.9 | T16: 1 | U16: =(K16*N16+O16)*R16*S16*T16 -> 85017.674
G18: 攻击力 | H18: 倍率 | I18: 独立 | J18: 独立 | K18: 基础乘区 | L18: 冰增伤 | M18: 暴击率 | N18: 爆伤 | O18: 暴击乘区 | P18: 抗性系数 | Q18: 单次伤害 | R18: 次数 | S18: 单总伤 | T18: 总伤
G19: =3199+488+203 -> 3890 | H19: 1.03 | I19: 1 | J19: 1 | K19: =G19*H19*I19*J19 -> 4006.7 | L19: 1 | M19: 0.85 | N19: 2.22 | O19: =1+M19*N19 -> 2.887 | P19: 1.15 | Q19: =K19*L19*O19*P19 -> 13302.444 | R19: 18 | S19: =Q19*R19 -> 239444 | T19: =SUM(S19:S25) -> 477229.5
G20: =3199+488+203 -> 3890 | H20: 1.5879 | I20: 3 | J20: 1 | K20: =G20*H20*I20*J20 -> 18530.793 | L20: 1 | M20: 0.85 | N20: 2.22 | O20: =1+M20*N20 -> 2.887 | P20: 1.15 | Q20: =K20*L20*O20*P20 -> 61523.159 | R20: 1 | S20: =Q20*R20 -> 61523.159
G21: =3199+488+203 -> 3890 | H21: 0.5832 | I21: 1 | J21: 1 | K21: =G21*H21*I21*J21 -> 2268.648 | L21: 1 | M21: 0.85 | N21: 2.22 | O21: =1+M21*N21 -> 2.887 | P21: 1.15 | Q21: =K21*L21*O21*P21 -> 7532.0248 | R21: 1 | S21: =Q21*R21 -> 7532.0248
G22: =G11 -> 3402 | H22: 1.03 | I22: 1 | J22: 1 | K22: =G22*H22*I22*J22 -> 3504.06 | L22: 1 | M22: 0.85 | N22: 2.22 | O22: =1+M22*N22 -> 2.887 | P22: 0.9 | Q22: =K22*L22*O22*P22 -> 9104.5991 | R22: 18 | S22: =Q22*R22 -> 163882.78
G23: =G16 -> 3199 | H23: 0.5832 | I23: 1 | J23: 1 | K23: =G23*H23*I23*J23 -> 1865.6568 | L23: 1 | M23: 0.85 | N23: 2.22 | O23: =1+M23*N23 -> 2.887 | P23: 0.9 | Q23: =K23*L23*O23*P23 -> 4847.5361 | R23: 1 | S23: =Q23*R23 -> 4847.5361
F25: 奥黛塔
F26: mc | G26: 攻击力 | H26: 倍率 | I26: 基础系数 | J26: 独立 | K26: 基础乘区 | L26: 精通 | M26: 星扩增 | N26: 精通乘区 | O26: 羽毛 | P26: 暴击率 | Q26: 爆伤 | R26: 暴击乘区 | S26: 抗性系数 | T26: 擢升 | U26: 单次伤害 | V26: 总伤
F27: ee | G27: 2604 | H27: 8.2555 | I27: 1.28 | J27: =16*0.015+1 -> 1.24 | K27: =G27*H27*I27*J27 -> 34120.549 | L27: 20 | M27: 1.1 | N27: =1+6*L27/(L27+2000)+M27 -> 2.1594059 | O27: 0 | P27: 0.93 | Q27: 2.3 | R27: =1+P27*Q27 -> 3.139 | S27: 0.9 | T27: 1 | U27: =(K27*N27+O27)*R27*S27*T27 -> 208153.7 | V27: =SUM(U27:U36) -> 449480.94
F28: e1 | G28: =189+2604 -> 2793 | H28: 0.7295 | I28: 1.28 | J28: =17*0.015+1 -> 1.255 | K28: =G28*H28*I28*J28 -> 3273.0296 | L28: 20 | M28: 1.3 | N28: =1+6*L28/(L28+2000)+M28 -> 2.3594059 | O28: 0 | P28: 0.93 | Q28: 2.3 | R28: =1+P28*Q28 -> 3.139 | S28: 0.9 | T28: 1 | U28: =(K28*N28+O28)*R28*S28*T28 -> 21816.567
F29: e2 | G29: =189+2604 -> 2793 | H29: 0.8724 | I29: 1.28 | J29: =17*0.015+1 -> 1.255 | K29: =G29*H29*I29*J29 -> 3914.1754 | L29: 20 | M29: 1.3 | N29: =1+6*L29/(L29+2000)+M29 -> 2.3594059 | O29: 0 | P29: 0.93 | Q29: 2.3 | R29: =1+P29*Q29 -> 3.139 | S29: 1.15 | T29: 1 | U29: =(K29*N29+O29)*R29*S29*T29 -> 33337.43
F30: e3 | G30: =189+2604 -> 2793 | H30: 0.7295 | I30: 1.28 | J30: =17*0.015+1 -> 1.255 | K30: =G30*H30*I30*J30 -> 3273.0296 | L30: 20 | M30: 1.3 | N30: =1+6*L30/(L30+2000)+M30 -> 2.3594059 | O30: 0 | P30: 0.93 | Q30: 2.3 | R30: =1+P30*Q30 -> 3.139 | S30: 1.15 | T30: 1 | U30: =(K30*N30+O30)*R30*S30*T30 -> 27876.725
F31: e4 | G31: =189+2604 -> 2793 | H31: 0.8724 | I31: 1.28 | J31: =17*0.015+1 -> 1.255 | K31: =G31*H31*I31*J31 -> 3914.1754 | L31: 20 | M31: 1.3 | N31: =1+6*L31/(L31+2000)+M31 -> 2.3594059 | O31: 0 | P31: 0.93 | Q31: 2.3 | R31: =1+P31*Q31 -> 3.139 | S31: 1.15 | T31: 1 | U31: =(K31*N31+O31)*R31*S31*T31 -> 33337.43
F32: e5 | G32: =189+2604 -> 2793 | H32: 0.7295 | I32: 1.28 | J32: =17*0.015+1 -> 1.255 | K32: =G32*H32*I32*J32 -> 3273.0296 | L32: 20 | M32: 1.3 | N32: =1+6*L32/(L32+2000)+M32 -> 2.3594059 | O32: 0 | P32: 0.93 | Q32: 2.3 | R32: =1+P32*Q32 -> 3.139 | S32: 1.15 | T32: 1 | U32: =(K32*N32+O32)*R32*S32*T32 -> 27876.725
F33: e6 | G33: =189+2604 -> 2793 | H33: 0.8724 | I33: 1.28 | J33: =17*0.015+1 -> 1.255 | K33: =G33*H33*I33*J33 -> 3914.1754 | L33: 20 | M33: 1.3 | N33: =1+6*L33/(L33+2000)+M33 -> 2.3594059 | O33: 0 | P33: 0.93 | Q33: 2.3 | R33: =1+P33*Q33 -> 3.139 | S33: 1.15 | T33: 1 | U33: =(K33*N33+O33)*R33*S33*T33 -> 33337.43
F34: e7 | G34: =189+2604 -> 2793 | H34: 0.7295 | I34: 1.28 | J34: =17*0.015+1 -> 1.255 | K34: =G34*H34*I34*J34 -> 3273.0296 | L34: 20 | M34: 1.3 | N34: =1+6*L34/(L34+2000)+M34 -> 2.3594059 | O34: 0 | P34: 0.93 | Q34: 2.3 | R34: =1+P34*Q34 -> 3.139 | S34: 0.9 | T34: 1 | U34: =(K34*N34+O34)*R34*S34*T34 -> 21816.567
F35: e8 | G35: =189+2604 -> 2793 | H35: 0.8724 | I35: 1.28 | J35: =17*0.015+1 -> 1.255 | K35: =G35*H35*I35*J35 -> 3914.1754 | L35: 20 | M35: 1.3 | N35: =1+6*L35/(L35+2000)+M35 -> 2.3594059 | O35: 0 | P35: 0.93 | Q35: 2.3 | R35: =1+P35*Q35 -> 3.139 | S35: 0.9 | T35: 1 | U35: =(K35*N35+O35)*R35*S35*T35 -> 26090.162
F36: e9 | G36: 2604 | H36: 0.7295 | I36: 1.28 | J36: 1.24 | K36: =G36*H36*I36*J36 -> 3015.0737 | L36: 20 | M36: 0.8 | N36: =1+6*L36/(L36+2000)+M36 -> 1.8594059 | O36: 0 | P36: 0.93 | Q36: 2.3 | R36: =1+P36*Q36 -> 3.139 | S36: 0.9 | T36: 1 | U36: =(K36*N36+O36)*R36*S36*T36 -> 15838.205
G38: 攻击力 | H38: 倍率 | I38: 独立 | J38: 独立 | K38: 基础乘区 | L38: 冰增伤 | M38: 暴击率 | N38: 爆伤 | O38: 暴击乘区 | P38: 抗性系数 | Q38: 单次伤害 | R38: 次数 | S38: 单总伤 | T38: 总伤
G39: =G27 -> 2604 | H39: 1.9454 | I39: 1 | J39: 1 | K39: =G39*H39*I39*J39 -> 5065.8216 | L39: 1 | M39: 0.93 | N39: 2.3 | O39: =1+M39*N39 -> 3.139 | P39: 0.9 | Q39: =K39*L39*O39*P39 -> 14311.453 | R39: 1 | S39: =Q39*R39 -> 14311.453 | T39: =SUM(S39:S40) -> 136818.63
G40: =G31 -> 2793 | H40: 1.7251 | I40: 1 | J40: 1 | K40: =G40*H40*I40*J40 -> 4818.2043 | L40: 1 | M40: 0.93 | N40: 2.3 | O40: =1+M40*N40 -> 3.139 | P40: 0.9 | Q40: =K40*L40*O40*P40 -> 13611.909 | R40: 9 | S40: =Q40*R40 -> 122507.18
F42: 冰涡
G43: 反应系数 | H43: 冰系数 | I43: 基础系数 | J43: 精通 | K43: 星扩增 | L43: 精通乘区 | M43: 暴击率 | N43: 爆伤 | O43: 暴击乘区 | P43: 抗性系数 | Q43: 擢升 | R43: 权重 | S43: xp伤害 | T43: 触发次数 | U43: 总伤
F44: p1 | G44: 1446.85 | H44: 2 | I44: 1.28 | J44: 200 | K44: 2.38 | L44: =1+6*J44/(J44+2000)+K44 -> 3.9254545 | M44: 0.85 | N44: 2.22 | O44: =1+M44*N44 -> 2.887 | P44: 1.15 | Q44: 1 | R44: 0.6 | S44: =G44*H44*I44*L44*O44*P44*Q44*R44 -> 28963.384 | T44: 2 | U44: =T46*T44 -> 73393.794
...

Sheet 4+1桑0奥 
A1: 4＋1桑多涅0＋星峰剑奥c6布0七 | F1: mc | G1: 攻击力 | H1: 倍率 | I1: 基础系数 | J1: 独立 | K1: 基础乘区 | L1: 精通 | M1: 星扩增 | N1: 精通乘区 | O1: 羽毛 | P1: 暴击率 | Q1: 爆伤 | R1: 暴击乘区 | S1: 抗性系数 | T1: 擢升 | U1: 单次伤害 | V1: 总伤
A2: 统计 | B2: DMG | C2: DPS | D2: 轴长 | F2: z | G2: =3199+488+203 -> 3890 | H2: 2.9355 | I2: 1.28 | J2: 1 | K2: =G2*H2*I2*J2 -> 14616.442 | L2: 200 | M2: 2.23 | N2: =1+6*L2/(L2+2000)+M2 -> 3.7754545 | O2: 0 | P2: 0.85 | Q2: 2.62 | R2: =1+P2*Q2 -> 3.227 | S2: 1.15 | T2: 1 | U2: =(K2*N2+O2)*R2*S2*T2 -> 204789.51 | V2: =SUM(U2:U20) -> 3783723
B3: =B5+B7+B9 -> 5039333.7 | C3: =B3/D3 -> 234387.61 | D3: 21.5 | F3: c4 | G3: =3199+488+203 -> 3890 | H3: 1.875 | I3: 1.28 | J3: 1 | K3: =G3*H3*I3*J3 -> 9336 | L3: 200 | M3: 2.23 | N3: =1+6*L3/(L3+2000)+M3 -> 3.7754545 | O3: 0 | P3: 0.85 | Q3: 2.22 | R3: =1+P3*Q3 -> 2.887 | S3: 1.15 | T3: 1 | U3: =(K3*N3+O3)*R3*S3*T3 -> 117023.94
B4: 桑多涅总伤 | C4: 占比 | F4: z | G4: =3199+488+203 -> 3890 | H4: 2.9355 | I4: 1.28 | J4: 1 | K4: =G4*H4*I4*J4 -> 14616.442 | L4: 200 | M4: 2.38 | N4: =1+6*L4/(L4+2000)+M4 -> 3.9254545 | O4: 0 | P4: 0.85 | Q4: 2.82 | R4: =1+P4*Q4 -> 3.397 | S4: 1.15 | T4: 1 | U4: =(K4*N4+O4)*R4*S4*T4 -> 224142.9
B5: =V2+T23 -> 4260952.5 | C5: =B5/B3 -> 0.84553887 | F5: z | G5: =3199+488+203 -> 3890 | H5: 2.9355 | I5: 1.28 | J5: 1 | K5: =G5*H5*I5*J5 -> 14616.442 | L5: 200 | M5: 2.38 | N5: =1+6*L5/(L5+2000)+M5 -> 3.9254545 | O5: 0 | P5: 0.85 | Q5: 3.02 | R5: =1+P5*Q5 -> 3.567 | S5: 1.15 | T5: 1 | U5: =(K5*N5+O5)*R5*S5*T5 -> 235359.95
B6: 奥黛塔总伤 | C6: 占比 | F6: z | G6: =3199+488+203 -> 3890 | H6: 2.9355 | I6: 1.28 | J6: 1 | K6: =G6*H6*I6*J6 -> 14616.442 | L6: 200 | M6: 2.38 | N6: =1+6*L6/(L6+2000)+M6 -> 3.9254545 | O6: 0 | P6: 0.85 | Q6: 3.22 | R6: =1+P6*Q6 -> 3.737 | S6: 1.15 | T6: 1 | U6: =(K6*N6+O6)*R6*S6*T6 -> 246576.99
B7: =V31+T43 -> 586299.57 | C7: =B7/B3 -> 0.11634466 | F7: c4 | G7: =3199+488+203 -> 3890 | H7: 1.875 | I7: 1.28 | J7: 1 | K7: =G7*H7*I7*J7 -> 9336 | L7: 200 | M7: 2.38 | N7: =1+6*L7/(L7+2000)+M7 -> 3.9254545 | O7: 0 | P7: 0.85 | Q7: 2.22 | R7: =1+P7*Q7 -> 2.887 | S7: 1.15 | T7: 1 | U7: =(K7*N7+O7)*R7*S7*T7 -> 121673.34
B8: 反应伤害 | C8: 占比 | F8: z | G8: =3199+488+203 -> 3890 | H8: 2.9355 | I8: 1.28 | J8: 1 | K8: =G8*H8*I8*J8 -> 14616.442 | L8: 200 | M8: 2.38 | N8: =1+6*L8/(L8+2000)+M8 -> 3.9254545 | O8: 0 | P8: 0.85 | Q8: 3.22 | R8: =1+P8*Q8 -> 3.737 | S8: 1.15 | T8: 1 | U8: =(K8*N8+O8)*R8*S8*T8 -> 246576.99
B9: =U48+U54+U60+U66 -> 192081.61 | C9: =B9/B3 -> 0.038116469 | F9: z | G9: =3199+488+203 -> 3890 | H9: 2.9355 | I9: 1.28 | J9: 1 | K9: =G9*H9*I9*J9 -> 14616.442 | L9: 200 | M9: 2.38 | N9: =1+6*L9/(L9+2000)+M9 -> 3.9254545 | O9: 0 | P9: 0.85 | Q9: 3.22 | R9: =1+P9*Q9 -> 3.737 | S9: 1.15 | T9: 1 | U9: =(K9*N9+O9)*R9*S9*T9 -> 246576.99
F10: q | G10: =3199+488+203 -> 3890 | H10: 5.9544 | I10: 1.28 | J10: 2 | K10: =G10*H10*I10*J10 -> 59296.297 | L10: 200 | M10: 2.38 | N10: =1+6*L10/(L10+2000)+M10 -> 3.9254545 | O10: 0 | P10: 0.85 | Q10: 2.22 | R10: =1+P10*Q10 -> 2.887 | S10: 1.15 | T10: 1 | U10: =(K10*N10+O10)*R10*S10*T10 -> 772791.17
F11: e | G11: =3199+488+203 -> 3890 | H11: 0.5832 | I11: 1.28 | J11: 4 | K11: =G11*H11*I11*J11 -> 11615.478 | L11: 200 | M11: 2.38 | N11: =1+6*L11/(L11+2000)+M11 -> 3.9254545 | O11: 0 | P11: 0.85 | Q11: 2.22 | R11: =1+P11*Q11 -> 2.887 | S11: 1.15 | T11: 1 | U11: =(K11*N11+O11)*R11*S11*T11 -> 151381.1
F12: c4 | G12: =3199+488+203 -> 3890 | H12: 1.875 | I12: 1.28 | J12: 1 | K12: =G12*H12*I12*J12 -> 9336 | L12: 200 | M12: 2.38 | N12: =1+6*L12/(L12+2000)+M12 -> 3.9254545 | O12: 0 | P12: 0.85 | Q12: 2.22 | R12: =1+P12*Q12 -> 2.887 | S12: 1.15 | T12: 1 | U12: =(K12*N12+O12)*R12*S12*T12 -> 121673.34
F13: z | G13: =3199+488+203 -> 3890 | H13: 2.9355 | I13: 1.28 | J13: 1 | K13: =G13*H13*I13*J13 -> 14616.442 | L13: 200 | M13: 2.38 | N13: =1+6*L13/(L13+2000)+M13 -> 3.9254545 | O13: 0 | P13: 0.85 | Q13: 2.62 | R13: =1+P13*Q13 -> 3.227 | S13: 0.9 | T13: 1 | U13: =(K13*N13+O13)*R13*S13*T13 -> 166637.63
F14: z | G14: =3199+203 -> 3402 | H14: 2.9355 | I14: 1.28 | J14: 1 | K14: =G14*H14*I14*J14 -> 12782.811 | L14: 200 | M14: 2.38 | N14: =1+6*L14/(L14+2000)+M14 -> 3.9254545 | O14: 0 | P14: 0.85 | Q14: 2.82 | R14: =1+P14*Q14 -> 3.397 | S14: 0.9 | T14: 1 | U14: =(K14*N14+O14)*R14*S14*T14 -> 153410.25
F15: z | G15: =3199+203 -> 3402 | H15: 2.9355 | I15: 1.28 | J15: 1 | K15: =G15*H15*I15*J15 -> 12782.811 | L15: 200 | M15: 2.38 | N15: =1+6*L15/(L15+2000)+M15 -> 3.9254545 | O15: 0 | P15: 0.85 | Q15: 3.02 | R15: =1+P15*Q15 -> 3.567 | S15: 0.9 | T15: 1 | U15: =(K15*N15+O15)*R15*S15*T15 -> 161087.53
F16: c4 | G16: =3199+203 -> 3402 | H16: 1.875 | I16: 1.28 | J16: 1 | K16: =G16*H16*I16*J16 -> 8164.8 | L16: 200 | M16: 2.38 | N16: =1+6*L16/(L16+2000)+M16 -> 3.9254545 | O16: 0 | P16: 0.85 | Q16: 2.22 | R16: =1+P16*Q16 -> 2.887 | S16: 0.9 | T16: 1 | U16: =(K16*N16+O16)*R16*S16*T16 -> 83276.947
F17: z | G17: =3199+203 -> 3402 | H17: 2.9355 | I17: 1.28 | J17: 1 | K17: =G17*H17*I17*J17 -> 12782.811 | L17: 200 | M17: 2.38 | N17: =1+6*L17/(L17+2000)+M17 -> 3.9254545 | O17: 0 | P17: 0.85 | Q17: 3.22 | R17: =1+P17*Q17 -> 3.737 | S17: 0.9 | T17: 1 | U17: =(K17*N17+O17)*R17*S17*T17 -> 168764.82
F18: z | G18: =3199 -> 3199 | H18: 2.9355 | I18: 1.28 | J18: 1 | K18: =G18*H18*I18*J18 -> 12020.051 | L18: 200 | M18: 1.88 | N18: =1+6*L18/(L18+2000)+M18 -> 3.4254545 | O18: 0 | P18: 0.85 | Q18: 3.22 | R18: =1+P18*Q18 -> 3.737 | S18: 0.9 | T18: 1 | U18: =(K18*N18+O18)*R18*S18*T18 -> 138480.97
F19: z | G19: =3199 -> 3199 | H19: 2.9355 | I19: 1.28 | J19: 1 | K19: =G19*H19*I19*J19 -> 12020.051 | L19: 200 | M19: 1.88 | N19: =1+6*L19/(L19+2000)+M19 -> 3.4254545 | O19: 0 | P19: 0.85 | Q19: 3.22 | R19: =1+P19*Q19 -> 3.737 | S19: 0.9 | T19: 1 | U19: =(K19*N19+O19)*R19*S19*T19 -> 138480.97
F20: e | G20: =3199 -> 3199 | H20: 0.5832 | I20: 1.28 | J20: 4 | K20: =G20*H20*I20*J20 -> 9552.1628 | L20: 200 | M20: 1.88 | N20: =1+6*L20/(L20+2000)+M20 -> 3.4254545 | O20: 0 | P20: 0.85 | Q20: 2.22 | R20: =1+P20*Q20 -> 2.887 | S20: 0.9 | T20: 1 | U20: =(K20*N20+O20)*R20*S20*T20 -> 85017.674
G22: 攻击力 | H22: 倍率 | I22: 独立 | J22: 独立 | K22: 基础乘区 | L22: 冰增伤 | M22: 暴击率 | N22: 爆伤 | O22: 暴击乘区 | P22: 抗性系数 | Q22: 单次伤害 | R22: 次数 | S22: 单总伤 | T22: 总伤
G23: =3199+488+203 -> 3890 | H23: 1.03 | I23: 1 | J23: 1 | K23: =G23*H23*I23*J23 -> 4006.7 | L23: 1 | M23: 0.85 | N23: 2.22 | O23: =1+M23*N23 -> 2.887 | P23: 1.15 | Q23: =K23*L23*O23*P23 -> 13302.444 | R23: 18 | S23: =Q23*R23 -> 239444 | T23: =SUM(S23:S29) -> 477229.5
G24: =3199+488+203 -> 3890 | H24: 1.5879 | I24: 3 | J24: 1 | K24: =G24*H24*I24*J24 -> 18530.793 | L24: 1 | M24: 0.85 | N24: 2.22 | O24: =1+M24*N24 -> 2.887 | P24: 1.15 | Q24: =K24*L24*O24*P24 -> 61523.159 | R24: 1 | S24: =Q24*R24 -> 61523.159
G25: =3199+488+203 -> 3890 | H25: 0.5832 | I25: 1 | J25: 1 | K25: =G25*H25*I25*J25 -> 2268.648 | L25: 1 | M25: 0.85 | N25: 2.22 | O25: =1+M25*N25 -> 2.887 | P25: 1.15 | Q25: =K25*L25*O25*P25 -> 7532.0248 | R25: 1 | S25: =Q25*R25 -> 7532.0248
G26: =G14 -> 3402 | H26: 1.03 | I26: 1 | J26: 1 | K26: =G26*H26*I26*J26 -> 3504.06 | L26: 1 | M26: 0.85 | N26: 2.22 | O26: =1+M26*N26 -> 2.887 | P26: 0.9 | Q26: =K26*L26*O26*P26 -> 9104.5991 | R26: 18 | S26: =Q26*R26 -> 163882.78
G27: =G20 -> 3199 | H27: 0.5832 | I27: 1 | J27: 1 | K27: =G27*H27*I27*J27 -> 1865.6568 | L27: 1 | M27: 0.85 | N27: 2.22 | O27: =1+M27*N27 -> 2.887 | P27: 0.9 | Q27: =K27*L27*O27*P27 -> 4847.5361 | R27: 1 | S27: =Q27*R27 -> 4847.5361
F29: 奥黛塔
F30: mc | G30: 攻击力 | H30: 倍率 | I30: 基础系数 | J30: 独立 | K30: 基础乘区 | L30: 精通 | M30: 星扩增 | N30: 精通乘区 | O30: 羽毛 | P30: 暴击率 | Q30: 爆伤 | R30: 暴击乘区 | S30: 抗性系数 | T30: 擢升 | U30: 单次伤害 | V30: 总伤
F31: ee | G31: 2604 | H31: 8.2555 | I31: 1.28 | J31: =16*0.015+1 -> 1.24 | K31: =G31*H31*I31*J31 -> 34120.549 | L31: 20 | M31: 1.1 | N31: =1+6*L31/(L31+2000)+M31 -> 2.1594059 | O31: 0 | P31: 0.93 | Q31: 2.3 | R31: =1+P31*Q31 -> 3.139 | S31: 0.9 | T31: 1 | U31: =(K31*N31+O31)*R31*S31*T31 -> 208153.7 | V31: =SUM(U31:U40) -> 449480.94
F32: e1 | G32: =189+2604 -> 2793 | H32: 0.7295 | I32: 1.28 | J32: =17*0.015+1 -> 1.255 | K32: =G32*H32*I32*J32 -> 3273.0296 | L32: 20 | M32: 1.3 | N32: =1+6*L32/(L32+2000)+M32 -> 2.3594059 | O32: 0 | P32: 0.93 | Q32: 2.3 | R32: =1+P32*Q32 -> 3.139 | S32: 0.9 | T32: 1 | U32: =(K32*N32+O32)*R32*S32*T32 -> 21816.567
F33: e2 | G33: =189+2604 -> 2793 | H33: 0.8724 | I33: 1.28 | J33: =17*0.015+1 -> 1.255 | K33: =G33*H33*I33*J33 -> 3914.1754 | L33: 20 | M33: 1.3 | N33: =1+6*L33/(L33+2000)+M33 -> 2.3594059 | O33: 0 | P33: 0.93 | Q33: 2.3 | R33: =1+P33*Q33 -> 3.139 | S33: 1.15 | T33: 1 | U33: =(K33*N33+O33)*R33*S33*T33 -> 33337.43
F34: e3 | G34: =189+2604 -> 2793 | H34: 0.7295 | I34: 1.28 | J34: =17*0.015+1 -> 1.255 | K34: =G34*H34*I34*J34 -> 3273.0296 | L34: 20 | M34: 1.3 | N34: =1+6*L34/(L34+2000)+M34 -> 2.3594059 | O34: 0 | P34: 0.93 | Q34: 2.3 | R34: =1+P34*Q34 -> 3.139 | S34: 1.15 | T34: 1 | U34: =(K34*N34+O34)*R34*S34*T34 -> 27876.725
F35: e4 | G35: =189+2604 -> 2793 | H35: 0.8724 | I35: 1.28 | J35: =17*0.015+1 -> 1.255 | K35: =G35*H35*I35*J35 -> 3914.1754 | L35: 20 | M35: 1.3 | N35: =1+6*L35/(L35+2000)+M35 -> 2.3594059 | O35: 0 | P35: 0.93 | Q35: 2.3 | R35: =1+P35*Q35 -> 3.139 | S35: 1.15 | T35: 1 | U35: =(K35*N35+O35)*R35*S35*T35 -> 33337.43
F36: e5 | G36: =189+2604 -> 2793 | H36: 0.7295 | I36: 1.28 | J36: =17*0.015+1 -> 1.255 | K36: =G36*H36*I36*J36 -> 3273.0296 | L36: 20 | M36: 1.3 | N36: =1+6*L36/(L36+2000)+M36 -> 2.3594059 | O36: 0 | P36: 0.93 | Q36: 2.3 | R36: =1+P36*Q36 -> 3.139 | S36: 1.15 | T36: 1 | U36: =(K36*N36+O36)*R36*S36*T36 -> 27876.725
F37: e6 | G37: =189+2604 -> 2793 | H37: 0.8724 | I37: 1.28 | J37: =17*0.015+1 -> 1.255 | K37: =G37*H37*I37*J37 -> 3914.1754 | L37: 20 | M37: 1.3 | N37: =1+6*L37/(L37+2000)+M37 -> 2.3594059 | O37: 0 | P37: 0.93 | Q37: 2.3 | R37: =1+P37*Q37 -> 3.139 | S37: 1.15 | T37: 1 | U37: =(K37*N37+O37)*R37*S37*T37 -> 33337.43
F38: e7 | G38: =189+2604 -> 2793 | H38: 0.7295 | I38: 1.28 | J38: =17*0.015+1 -> 1.255 | K38: =G38*H38*I38*J38 -> 3273.0296 | L38: 20 | M38: 1.3 | N38: =1+6*L38/(L38+2000)+M38 -> 2.3594059 | O38: 0 | P38: 0.93 | Q38: 2.3 | R38: =1+P38*Q38 -> 3.139 | S38: 0.9 | T38: 1 | U38: =(K38*N38+O38)*R38*S38*T38 -> 21816.567
F39: e8 | G39: =189+2604 -> 2793 | H39: 0.8724 | I39: 1.28 | J39: =17*0.015+1 -> 1.255 | K39: =G39*H39*I39*J39 -> 3914.1754 | L39: 20 | M39: 1.3 | N39: =1+6*L39/(L39+2000)+M39 -> 2.3594059 | O39: 0 | P39: 0.93 | Q39: 2.3 | R39: =1+P39*Q39 -> 3.139 | S39: 0.9 | T39: 1 | U39: =(K39*N39+O39)*R39*S39*T39 -> 26090.162
F40: e9 | G40: 2604 | H40: 0.7295 | I40: 1.28 | J40: 1.24 | K40: =G40*H40*I40*J40 -> 3015.0737 | L40: 20 | M40: 0.8 | N40: =1+6*L40/(L40+2000)+M40 -> 1.8594059 | O40: 0 | P40: 0.93 | Q40: 2.3 | R40: =1+P40*Q40 -> 3.139 | S40: 0.9 | T40: 1 | U40: =(K40*N40+O40)*R40*S40*T40 -> 15838.205
G42: 攻击力 | H42: 倍率 | I42: 独立 | J42: 独立 | K42: 基础乘区 | L42: 冰增伤 | M42: 暴击率 | N42: 爆伤 | O42: 暴击乘区 | P42: 抗性系数 | Q42: 单次伤害 | R42: 次数 | S42: 单总伤 | T42: 总伤
G43: =G31 -> 2604 | H43: 1.9454 | I43: 1 | J43: 1 | K43: =G43*H43*I43*J43 -> 5065.8216 | L43: 1 | M43: 0.93 | N43: 2.3 | O43: =1+M43*N43 -> 3.139 | P43: 0.9 | Q43: =K43*L43*O43*P43 -> 14311.453 | R43: 1 | S43: =Q43*R43 -> 14311.453 | T43: =SUM(S43:S44) -> 136818.63
...

Sheet 5+1桑0奥 
A1: 5＋1桑多涅0＋星峰剑奥c6布0七 | F1: mc | G1: 攻击力 | H1: 倍率 | I1: 基础系数 | J1: 独立 | K1: 基础乘区 | L1: 精通 | M1: 星扩增 | N1: 精通乘区 | O1: 羽毛 | P1: 暴击率 | Q1: 爆伤 | R1: 暴击乘区 | S1: 抗性系数 | T1: 擢升 | U1: 单次伤害 | V1: 总伤
A2: 统计 | B2: DMG | C2: DPS | D2: 轴长 | F2: z | G2: =3199+488+203 -> 3890 | H2: 2.9355 | I2: 1.28 | J2: 1 | K2: =G2*H2*I2*J2 -> 14616.442 | L2: 200 | M2: 2.23 | N2: =1+6*L2/(L2+2000)+M2 -> 3.7754545 | O2: 0 | P2: 0.85 | Q2: 2.62 | R2: =1+P2*Q2 -> 3.227 | S2: 1.15 | T2: 1 | U2: =(K2*N2+O2)*R2*S2*T2 -> 204789.51 | V2: =SUM(U2:U20) -> 3923254.8
B3: =B5+B7+B9 -> 5189973.6 | C3: =B3/D3 -> 241394.12 | D3: 21.5 | F3: c4 | G3: =3199+488+203 -> 3890 | H3: 1.875 | I3: 1.28 | J3: 1 | K3: =G3*H3*I3*J3 -> 9336 | L3: 200 | M3: 2.23 | N3: =1+6*L3/(L3+2000)+M3 -> 3.7754545 | O3: 0 | P3: 0.85 | Q3: 2.22 | R3: =1+P3*Q3 -> 2.887 | S3: 1.15 | T3: 1 | U3: =(K3*N3+O3)*R3*S3*T3 -> 117023.94
B4: 桑多涅总伤 | C4: 占比 | F4: z | G4: =3199+488+203 -> 3890 | H4: 2.9355 | I4: 1.28 | J4: 1 | K4: =G4*H4*I4*J4 -> 14616.442 | L4: 200 | M4: 2.38 | N4: =1+6*L4/(L4+2000)+M4 -> 3.9254545 | O4: 0 | P4: 0.85 | Q4: 2.82 | R4: =1+P4*Q4 -> 3.397 | S4: 1.15 | T4: 1 | U4: =(K4*N4+O4)*R4*S4*T4 -> 224142.9
B5: =V2+T23 -> 4411592.4 | C5: =B5/B3 -> 0.85002213 | F5: z | G5: =3199+488+203 -> 3890 | H5: 2.9355 | I5: 1.28 | J5: 1 | K5: =G5*H5*I5*J5 -> 14616.442 | L5: 200 | M5: 2.38 | N5: =1+6*L5/(L5+2000)+M5 -> 3.9254545 | O5: 0 | P5: 0.85 | Q5: 3.02 | R5: =1+P5*Q5 -> 3.567 | S5: 1.15 | T5: 1 | U5: =(K5*N5+O5)*R5*S5*T5 -> 235359.95
B6: 奥黛塔总伤 | C6: 占比 | F6: z | G6: =3199+488+203 -> 3890 | H6: 2.9355 | I6: 1.28 | J6: 1 | K6: =G6*H6*I6*J6 -> 14616.442 | L6: 200 | M6: 2.38 | N6: =1+6*L6/(L6+2000)+M6 -> 3.9254545 | O6: 0 | P6: 0.85 | Q6: 3.22 | R6: =1+P6*Q6 -> 3.737 | S6: 1.15 | T6: 1 | U6: =(K6*N6+O6)*R6*S6*T6 -> 246576.99
B7: =V31+T43 -> 586299.57 | C7: =B7/B3 -> 0.11296774 | F7: c4 | G7: =3199+488+203 -> 3890 | H7: 1.875 | I7: 1.28 | J7: 1 | K7: =G7*H7*I7*J7 -> 9336 | L7: 200 | M7: 2.38 | N7: =1+6*L7/(L7+2000)+M7 -> 3.9254545 | O7: 0 | P7: 0.85 | Q7: 2.22 | R7: =1+P7*Q7 -> 2.887 | S7: 1.15 | T7: 1 | U7: =(K7*N7+O7)*R7*S7*T7 -> 121673.34
B8: 反应伤害 | C8: 占比 | F8: z | G8: =3199+488+203 -> 3890 | H8: 2.9355 | I8: 1.28 | J8: 1 | K8: =G8*H8*I8*J8 -> 14616.442 | L8: 200 | M8: 2.38 | N8: =1+6*L8/(L8+2000)+M8 -> 3.9254545 | O8: 0 | P8: 0.85 | Q8: 3.22 | R8: =1+P8*Q8 -> 3.737 | S8: 1.15 | T8: 1 | U8: =(K8*N8+O8)*R8*S8*T8 -> 246576.99
B9: =U48+U54+U60+U66 -> 192081.61 | C9: =B9/B3 -> 0.037010132 | F9: z | G9: =3199+488+203 -> 3890 | H9: 2.9355 | I9: 1.28 | J9: 1 | K9: =G9*H9*I9*J9 -> 14616.442 | L9: 200 | M9: 2.38 | N9: =1+6*L9/(L9+2000)+M9 -> 3.9254545 | O9: 0 | P9: 0.85 | Q9: 3.22 | R9: =1+P9*Q9 -> 3.737 | S9: 1.15 | T9: 1 | U9: =(K9*N9+O9)*R9*S9*T9 -> 246576.99
F10: q | G10: =3199+488+203 -> 3890 | H10: 7.0295 | I10: 1.28 | J10: 2 | K10: =G10*H10*I10*J10 -> 70002.573 | L10: 200 | M10: 2.38 | N10: =1+6*L10/(L10+2000)+M10 -> 3.9254545 | O10: 0 | P10: 0.85 | Q10: 2.22 | R10: =1+P10*Q10 -> 2.887 | S10: 1.15 | T10: 1 | U10: =(K10*N10+O10)*R10*S10*T10 -> 912322.91
F11: e | G11: =3199+488+203 -> 3890 | H11: 0.5832 | I11: 1.28 | J11: 4 | K11: =G11*H11*I11*J11 -> 11615.478 | L11: 200 | M11: 2.38 | N11: =1+6*L11/(L11+2000)+M11 -> 3.9254545 | O11: 0 | P11: 0.85 | Q11: 2.22 | R11: =1+P11*Q11 -> 2.887 | S11: 1.15 | T11: 1 | U11: =(K11*N11+O11)*R11*S11*T11 -> 151381.1
F12: c4 | G12: =3199+488+203 -> 3890 | H12: 1.875 | I12: 1.28 | J12: 1 | K12: =G12*H12*I12*J12 -> 9336 | L12: 200 | M12: 2.38 | N12: =1+6*L12/(L12+2000)+M12 -> 3.9254545 | O12: 0 | P12: 0.85 | Q12: 2.22 | R12: =1+P12*Q12 -> 2.887 | S12: 1.15 | T12: 1 | U12: =(K12*N12+O12)*R12*S12*T12 -> 121673.34
F13: z | G13: =3199+488+203 -> 3890 | H13: 2.9355 | I13: 1.28 | J13: 1 | K13: =G13*H13*I13*J13 -> 14616.442 | L13: 200 | M13: 2.38 | N13: =1+6*L13/(L13+2000)+M13 -> 3.9254545 | O13: 0 | P13: 0.85 | Q13: 2.62 | R13: =1+P13*Q13 -> 3.227 | S13: 0.9 | T13: 1 | U13: =(K13*N13+O13)*R13*S13*T13 -> 166637.63
F14: z | G14: =3199+203 -> 3402 | H14: 2.9355 | I14: 1.28 | J14: 1 | K14: =G14*H14*I14*J14 -> 12782.811 | L14: 200 | M14: 2.38 | N14: =1+6*L14/(L14+2000)+M14 -> 3.9254545 | O14: 0 | P14: 0.85 | Q14: 2.82 | R14: =1+P14*Q14 -> 3.397 | S14: 0.9 | T14: 1 | U14: =(K14*N14+O14)*R14*S14*T14 -> 153410.25
F15: z | G15: =3199+203 -> 3402 | H15: 2.9355 | I15: 1.28 | J15: 1 | K15: =G15*H15*I15*J15 -> 12782.811 | L15: 200 | M15: 2.38 | N15: =1+6*L15/(L15+2000)+M15 -> 3.9254545 | O15: 0 | P15: 0.85 | Q15: 3.02 | R15: =1+P15*Q15 -> 3.567 | S15: 0.9 | T15: 1 | U15: =(K15*N15+O15)*R15*S15*T15 -> 161087.53
F16: c4 | G16: =3199+203 -> 3402 | H16: 1.875 | I16: 1.28 | J16: 1 | K16: =G16*H16*I16*J16 -> 8164.8 | L16: 200 | M16: 2.38 | N16: =1+6*L16/(L16+2000)+M16 -> 3.9254545 | O16: 0 | P16: 0.85 | Q16: 2.22 | R16: =1+P16*Q16 -> 2.887 | S16: 0.9 | T16: 1 | U16: =(K16*N16+O16)*R16*S16*T16 -> 83276.947
F17: z | G17: =3199+203 -> 3402 | H17: 2.9355 | I17: 1.28 | J17: 1 | K17: =G17*H17*I17*J17 -> 12782.811 | L17: 200 | M17: 2.38 | N17: =1+6*L17/(L17+2000)+M17 -> 3.9254545 | O17: 0 | P17: 0.85 | Q17: 3.22 | R17: =1+P17*Q17 -> 3.737 | S17: 0.9 | T17: 1 | U17: =(K17*N17+O17)*R17*S17*T17 -> 168764.82
F18: z | G18: =3199 -> 3199 | H18: 2.9355 | I18: 1.28 | J18: 1 | K18: =G18*H18*I18*J18 -> 12020.051 | L18: 200 | M18: 1.88 | N18: =1+6*L18/(L18+2000)+M18 -> 3.4254545 | O18: 0 | P18: 0.85 | Q18: 3.22 | R18: =1+P18*Q18 -> 3.737 | S18: 0.9 | T18: 1 | U18: =(K18*N18+O18)*R18*S18*T18 -> 138480.97
F19: z | G19: =3199 -> 3199 | H19: 2.9355 | I19: 1.28 | J19: 1 | K19: =G19*H19*I19*J19 -> 12020.051 | L19: 200 | M19: 1.88 | N19: =1+6*L19/(L19+2000)+M19 -> 3.4254545 | O19: 0 | P19: 0.85 | Q19: 3.22 | R19: =1+P19*Q19 -> 3.737 | S19: 0.9 | T19: 1 | U19: =(K19*N19+O19)*R19*S19*T19 -> 138480.97
